Workbook
Name IQ_CH: 110000
Name IQ_CQ: 5000
Name IQ_CY: 10000
Name IQ_DAILY: 500000
Name IQ_FH: 100000
Name IQ_FQ: 500
Name IQ_FY: 1000
Name IQ_LTM: 2000
Name IQ_MONTH: 15000
Name IQ_NTM: 6000
Name IQ_WEEK: 50000
Name IQ_YTD: 3000
Name UPDATE: '[1]Data Sheet'!$E$1
Name UPDATE: 'Data Sheet'!$E$1

Sheet Financials>

Sheet HistoricalFS
B2: ='Data Sheet'!B1 -> GODREJ CONSUMER PRODUCTS LTD
B3: (GODREJCP | BSE Code: 532424)
B5: ="Historical Financial Statement - "&'Data Sheet'!B1 -> Historical Financial Statement - GODREJ CONSUMER PRODUCTS LTD
B6: Years | C6: ='Data Sheet'!B16 -> 42094 | D6: ='Data Sheet'!C16 -> 42460 | E6: ='Data Sheet'!D16 -> 42825 | F6: ='Data Sheet'!E16 -> 43190 | G6: ='Data Sheet'!F16 -> 43555 | H6: ='Data Sheet'!G16 -> 43921 | I6: ='Data Sheet'!H16 -> 44286 | J6: ='Data Sheet'!I16 -> 44651 | ... L6: ='Data Sheet'!K16 -> 45382
A8: # | B8: Income Statement
B9: Sales | C9: =IFERROR('Data Sheet'!B17,0) -> 8273.15 | D9: =IFERROR('Data Sheet'!C17,0) -> 8423.88 | E9: =IFERROR('Data Sheet'!D17,0) -> 9267.91 | F9: =IFERROR('Data Sheet'!E17,0) -> 9847.43 | G9: =IFERROR('Data Sheet'!F17,0) -> 10314.34 | H9: =IFERROR('Data Sheet'!G17,0) -> 9910.8 | I9: =IFERROR('Data Sheet'!H17,0) -> 11028.62 | J9: =IFERROR('Data Sheet'!I17,0) -> 12276.5 | ... L9: =IFERROR('Data Sheet'!K17,0) -> 14096.11
B10: Sales Growth | C10: - | D10: =D9/C9-1 -> 0.018219179 | E10: =E9/D9-1 -> 0.10019492 | F10: =F9/E9-1 -> 0.06252974 | G10: =G9/F9-1 -> 0.047414402 | H10: =H9/G9-1 -> -0.039124171 | I10: =I9/H9-1 -> 0.11278807 | J10: =J9/I9-1 -> 0.11314924 | K10: =K9/J9-1 -> 0.084671527 | L10: =L9/K9-1 -> 0.058586795
B12: COGS | C12: =IFERROR(SUM('Data Sheet'!B18,'Data Sheet'!B20:B22)-1*'Data Sheet'!B19,0) -> 4952.36 | D12: =IFERROR(SUM('Data Sheet'!C18,'Data Sheet'!C20:C22)-1*'Data Sheet'!C19,0) -> 5157.59 | E12: =IFERROR(SUM('Data Sheet'!D18,'Data Sheet'!D20:D22)-1*'Data Sheet'!D19,0) -> 5512.85 | F12: =IFERROR(SUM('Data Sheet'!E18,'Data Sheet'!E20:E22)-1*'Data Sheet'!E19,0) -> 5751.63 | G12: =IFERROR(SUM('Data Sheet'!F18,'Data Sheet'!F20:F22)-1*'Data Sheet'!F19,0) -> 6071.83 | H12: =IFERROR(SUM('Data Sheet'!G18,'Data Sheet'!G20:G22)-1*'Data Sheet'!G19,0) -> 5777.48 | I12: =IFERROR(SUM('Data Sheet'!H18,'Data Sheet'!H20:H22)-1*'Data Sheet'!H19,0) -> 6556.24 | J12: =IFERROR(SUM('Data Sheet'!I18,'Data Sheet'!I20:I22)-1*'Data Sheet'!I19,0) -> 7743.02 | ... L12: =IFERROR(SUM('Data Sheet'!K18,'Data Sheet'!K20:K22)-1*'Data Sheet'!K19,0) -> 8140.92
B13: COGS % Sales | C13: =C12/C9 -> 0.59860633 | D13: =D12/D9 -> 0.61225825 | E13: =E12/E9 -> 0.59483206 | F13: =F12/F9 -> 0.58407422 | G13: =G12/G9 -> 0.58867848 | H13: =H12/H9 -> 0.5829479 | I13: =I12/I9 -> 0.5944751 | J13: =J12/J9 -> 0.63071885 | ... L13: =L12/L9 -> 0.57752955
B15: Gross Profit | C15: =C9-C12 -> 3320.79 | D15: =D9-D12 -> 3266.29 | E15: =E9-E12 -> 3755.06 | F15: =F9-F12 -> 4095.8 | G15: =G9-G12 -> 4242.51 | H15: =H9-H12 -> 4133.32 | I15: =I9-I12 -> 4472.38 | J15: =J9-J12 -> 4533.48 | ... L15: =L9-L12 -> 5955.19
B16: Gross Margins | C16: =C15/C9 -> 0.40139367 | D16: =D15/D9 -> 0.38774175 | E16: =E15/E9 -> 0.40516794 | F16: =F15/F9 -> 0.41592578 | G16: =G15/G9 -> 0.41132152 | H16: =H15/H9 -> 0.4170521 | I16: =I15/I9 -> 0.4055249 | J16: =J15/J9 -> 0.36928115 | ... L16: =L15/L9 -> 0.42247045
B18: Selling & General Expenses | C18: =IFERROR(SUM('Data Sheet'!B23:B24),0) -> 1941.84 | D18: =IFERROR(SUM('Data Sheet'!C23:C24),0) -> 1608.91 | E18: =IFERROR(SUM('Data Sheet'!D23:D24),0) -> 1848.35 | F18: =IFERROR(SUM('Data Sheet'!E23:E24),0) -> 2011.4 | G18: =IFERROR(SUM('Data Sheet'!F23:F24),0) -> 2110.94 | H18: =IFERROR(SUM('Data Sheet'!G23:G24),0) -> 1979.57 | I18: =IFERROR(SUM('Data Sheet'!H23:H24),0) -> 2073.12 | J18: =IFERROR(SUM('Data Sheet'!I23:I24),0) -> 2124.3 | ... L18: =IFERROR(SUM('Data Sheet'!K23:K24),0) -> 2997.87
B19: S&G Exp % Sales | C19: =C18/C9 -> 0.23471592 | D19: =D18/D9 -> 0.19099394 | E19: =E18/E9 -> 0.19943547 | F19: =F18/F9 -> 0.20425634 | G19: =G18/G9 -> 0.2046607 | H19: =H18/H9 -> 0.19973867 | I19: =I18/I9 -> 0.18797637 | J19: =J18/J9 -> 0.17303792 | ... L19: =L18/L9 -> 0.21267357
B21: EBITDA | C21: =C15-C18 -> 1378.95 | D21: =D15-D18 -> 1657.38 | E21: =E15-E18 -> 1906.71 | F21: =F15-F18 -> 2084.4 | G21: =G15-G18 -> 2131.57 | H21: =H15-H18 -> 2153.75 | I21: =I15-I18 -> 2399.26 | J21: =J15-J18 -> 2409.18 | ... L21: =L15-L18 -> 2957.32
B22: EBITDA Margins | C22: =C21/C9 -> 0.16667775 | D22: =D21/D9 -> 0.19674782 | E22: =E21/E9 -> 0.20573247 | F22: =F21/F9 -> 0.21166944 | G22: =G21/G9 -> 0.20666082 | H22: =H21/H9 -> 0.21731344 | I22: =I21/I9 -> 0.21754852 | J22: =J21/J9 -> 0.19624323 | ... L22: =L21/L9 -> 0.20979689
B24: Interest | C24: =IFERROR('Data Sheet'!B27,0) -> 112.46 | D24: =IFERROR('Data Sheet'!C27,0) -> 128.04 | E24: =IFERROR('Data Sheet'!D27,0) -> 154.19 | F24: =IFERROR('Data Sheet'!E27,0) -> 173.12 | G24: =IFERROR('Data Sheet'!F27,0) -> 238.21 | H24: =IFERROR('Data Sheet'!G27,0) -> 228.13 | I24: =IFERROR('Data Sheet'!H27,0) -> 137.65 | J24: =IFERROR('Data Sheet'!I27,0) -> 122.26 | ... L24: =IFERROR('Data Sheet'!K27,0) -> 309.57
B25: Interest % Sales | C25: =C24/C9 -> 0.013593371 | D25: =D24/D9 -> 0.015199647 | E25: =E24/E9 -> 0.016636976 | F25: =F24/F9 -> 0.017580221 | G25: =G24/G9 -> 0.023095031 | H25: =H24/H9 -> 0.023018323 | I25: =I24/I9 -> 0.012481163 | J25: =J24/J9 -> 0.0099588645 | ... L25: =L24/L9 -> 0.021961378
B27: Depreciation | C27: =IFERROR('Data Sheet'!B26,0) -> 90.78 | D27: =IFERROR('Data Sheet'!C26,0) -> 100.63 | E27: =IFERROR('Data Sheet'!D26,0) -> 141.57 | F27: =IFERROR('Data Sheet'!E26,0) -> 155.68 | G27: =IFERROR('Data Sheet'!F26,0) -> 169.98 | H27: =IFERROR('Data Sheet'!G26,0) -> 197.28 | I27: =IFERROR('Data Sheet'!H26,0) -> 203.85 | J27: =IFERROR('Data Sheet'!I26,0) -> 209.93 | ... L27: =IFERROR('Data Sheet'!K26,0) -> 240.96
B28: Depreciation%Sales | C28: =C27/C9 -> 0.010972846 | D28: =D27/D9 -> 0.011945802 | E28: =E27/E9 -> 0.015275289 | F28: =F27/F9 -> 0.015809201 | G28: =G27/G9 -> 0.016479969 | H28: =H27/H9 -> 0.019905558 | I28: =I27/I9 -> 0.018483727 | J28: =J27/J9 -> 0.017100151 | ... L28: =L27/L9 -> 0.017094078
B30: Earnings Before Tax | C30: =IFERROR(C21-SUM(C27,C24),0) -> 1175.71 | D30: =IFERROR(D21-SUM(D27,D24),0) -> 1428.71 | E30: =IFERROR(E21-SUM(E27,E24),0) -> 1610.95 | F30: =IFERROR(F21-SUM(F27,F24),0) -> 1755.6 | G30: =IFERROR(G21-SUM(G27,G24),0) -> 1723.38 | H30: =IFERROR(H21-SUM(H27,H24),0) -> 1728.34 | I30: =IFERROR(I21-SUM(I27,I24),0) -> 2057.76 | J30: =IFERROR(J21-SUM(J27,J24),0) -> 2076.99 | ... L30: =IFERROR(L21-SUM(L27,L24),0) -> 2406.79
B31: EBT % Sales | C31: =C30/C9 -> 0.14211153 | D31: =D30/D9 -> 0.16960237 | E31: =E30/E9 -> 0.1738202 | F31: =F30/F9 -> 0.17828002 | G31: =G30/G9 -> 0.16708582 | H31: =H30/H9 -> 0.17438955 | I31: =I30/I9 -> 0.18658363 | J31: =J30/J9 -> 0.16918421 | ... L31: =L30/L9 -> 0.17074143
B33: Tax | C33: =IFERROR('Data Sheet'!B29,0) -> 272.29 | D33: =IFERROR('Data Sheet'!C29,0) -> 336.05 | E33: =IFERROR('Data Sheet'!D29,0) -> 379.16 | F33: =IFERROR('Data Sheet'!E29,0) -> 404.7 | G33: =IFERROR('Data Sheet'!F29,0) -> -256.2 | H33: =IFERROR('Data Sheet'!G29,0) -> 263.82 | I33: =IFERROR('Data Sheet'!H29,0) -> 359.54 | J33: =IFERROR('Data Sheet'!I29,0) -> 371.87 | ... L33: =IFERROR('Data Sheet'!K29,0) -> 758.78
B34: Effective Tax Rate | C34: =C33/C30 -> 0.23159623 | D34: =D33/D30 -> 0.23521218 | E34: =E33/E30 -> 0.23536423 | F34: =F33/F30 -> 0.23051948 | G34: =G33/G30 -> -0.14866135 | H34: =H33/H30 -> 0.15264358 | I34: =I33/I30 -> 0.17472397 | J34: =J33/J30 -> 0.17904275 | ... L34: =L33/L30 -> 0.31526639
B36: Net Profit | C36: =IFERROR(C30-C33,0) -> 903.42 | D36: =IFERROR(D30-D33,0) -> 1092.66 | E36: =IFERROR(E30-E33,0) -> 1231.79 | F36: =IFERROR(F30-F33,0) -> 1350.9 | G36: =IFERROR(G30-G33,0) -> 1979.58 | H36: =IFERROR(H30-H33,0) -> 1464.52 | I36: =IFERROR(I30-I33,0) -> 1698.22 | J36: =IFERROR(J30-J33,0) -> 1705.12 | ... L36: =IFERROR(L30-L33,0) -> 1648.01
B37: Net Margins | C37: =C36/C9 -> 0.10919904 | D37: =D36/D9 -> 0.12970982 | E37: =E36/E9 -> 0.13290915 | F37: =F36/F9 -> 0.137183 | G37: =G36/G9 -> 0.19192503 | H37: =H36/H9 -> 0.14777011 | I37: =I36/I9 -> 0.153983 | J37: =J36/J9 -> 0.13889301 | ... L37: =L36/L9 -> 0.1169124
B39: No of Equity Shares | C39: =IFERROR('Data Sheet'!B93,0) -> 102.14 | D39: =IFERROR('Data Sheet'!C93,0) -> 102.16 | E39: =IFERROR('Data Sheet'!D93,0) -> 102.18 | F39: =IFERROR('Data Sheet'!E93,0) -> 102.2 | G39: =IFERROR('Data Sheet'!F93,0) -> 102.22 | H39: =IFERROR('Data Sheet'!G93,0) -> 102.23 | I39: =IFERROR('Data Sheet'!H93,0) -> 102.25 | J39: =IFERROR('Data Sheet'!I93,0) -> 102.26 | ... L39: =IFERROR('Data Sheet'!K93,0) -> 102.28
B41: Earnings per Share | C41: =IFERROR(C36/C39,0) -> 8.8449187 | D41: =IFERROR(D36/D39,0) -> 10.695576 | E41: =IFERROR(E36/E39,0) -> 12.055099 | F41: =IFERROR(F36/F39,0) -> 13.2182 | G41: =IFERROR(G36/G39,0) -> 19.365878 | H41: =IFERROR(H36/H39,0) -> 14.325736 | I41: =IFERROR(I36/I39,0) -> 16.608509 | J41: =IFERROR(J36/J39,0) -> 16.674359 | ... L41: =IFERROR(L36/L39,0) -> 16.11273
B42: EPS Growth % | D42: =IFERROR(D41/C41-1,0) -> 0.2092339 | E42: =IFERROR(E41/D41-1,0) -> 0.12711081 | F42: =IFERROR(F41/E41-1,0) -> 0.096482059 | G42: =IFERROR(G41/F41-1,0) -> 0.46509193 | H42: =IFERROR(H41/G41-1,0) -> -0.26025887 | I42: =IFERROR(I41/H41-1,0) -> 0.15934766 | J42: =IFERROR(J41/I41-1,0) -> 0.0039648905 | K42: =IFERROR(K41/J41-1,0) -> -0.068684486 | L42: =IFERROR(L41/K41-1,0) -> 0.037583665
B44: Dividend per Share | C44: =IFERROR('Data Sheet'!B31/HistoricalFS!C39,0) -> 1.8329743 | D44: =IFERROR('Data Sheet'!C31/HistoricalFS!D39,0) -> 1.9165035 | E44: =IFERROR('Data Sheet'!D31/HistoricalFS!E39,0) -> 5 | F44: =IFERROR('Data Sheet'!E31/HistoricalFS!F39,0) -> 6.6663405 | G44: =IFERROR('Data Sheet'!F31/HistoricalFS!G39,0) -> 10 | H44: =IFERROR('Data Sheet'!G31/HistoricalFS!H39,0) -> 8 | I44: =IFERROR('Data Sheet'!H31/HistoricalFS!I39,0) -> 0 | J44: =IFERROR('Data Sheet'!I31/HistoricalFS!J39,0) -> 0 | ... L44: =IFERROR('Data Sheet'!K31/HistoricalFS!L39,0) -> 0
B45: Dividend payout ratio | C45: =IFERROR(C44/C41,0) -> 0.20723473 | D45: =IFERROR(D44/D41,0) -> 0.17918657 | E45: =IFERROR(E44/E41,0) -> 0.41476226 | F45: =IFERROR(F44/F41,0) -> 0.50433045 | G45: =IFERROR(G44/G41,0) -> 0.51637216 | H45: =IFERROR(H44/H41,0) -> 0.55843553 | I45: =IFERROR(I44/I41,0) -> 0 | J45: =IFERROR(J44/J41,0) -> 0 | ... L45: =IFERROR(L44/L41,0) -> 0
B47: Retained Earnings | C47: =IFERROR(IF(C41>C44,1-C45,0),0) -> 0.79276527 | D47: =IFERROR(IF(D41>D44,1-D45,0),0) -> 0.82081343 | E47: =IFERROR(IF(E41>E44,1-E45,0),0) -> 0.58523774 | F47: =IFERROR(IF(F41>F44,1-F45,0),0) -> 0.49566955 | G47: =IFERROR(IF(G41>G44,1-G45,0),0) -> 0.48362784 | H47: =IFERROR(IF(H41>H44,1-H45,0),0) -> 0.44156447 | I47: =IFERROR(IF(I41>I44,1-I45,0),0) -> 1 | J47: =IFERROR(IF(J41>J44,1-J45,0),0) -> 1 | ... L47: =IFERROR(IF(L41>L44,1-L45,0),0) -> 1
A49: # | B49: Balance Sheet
B51: Equity Share Capital | C51: =IFERROR('Data Sheet'!B57,0) -> 34.04 | D51: =IFERROR('Data Sheet'!C57,0) -> 34.05 | E51: =IFERROR('Data Sheet'!D57,0) -> 34.06 | F51: =IFERROR('Data Sheet'!E57,0) -> 68.13 | G51: =IFERROR('Data Sheet'!F57,0) -> 102.22 | H51: =IFERROR('Data Sheet'!G57,0) -> 102.23 | I51: =IFERROR('Data Sheet'!H57,0) -> 102.25 | J51: =IFERROR('Data Sheet'!I57,0) -> 102.26 | ... L51: =IFERROR('Data Sheet'!K57,0) -> 102.28
B52: Reserves | C52: =IFERROR('Data Sheet'!B58,0) -> 4276.65 | D52: =IFERROR('Data Sheet'!C58,0) -> 4232.91 | E52: =IFERROR('Data Sheet'!D58,0) -> 5267.89 | F52: =IFERROR('Data Sheet'!E58,0) -> 6190.18 | G52: =IFERROR('Data Sheet'!F58,0) -> 7164.7 | H52: =IFERROR('Data Sheet'!G58,0) -> 7796.13 | I52: =IFERROR('Data Sheet'!H58,0) -> 9336.65 | J52: =IFERROR('Data Sheet'!I58,0) -> 11453.67 | ... L52: =IFERROR('Data Sheet'!K58,0) -> 12496.29
B53: Borrowings | C53: =IFERROR('Data Sheet'!B59,0) -> 2717.15 | D53: =IFERROR('Data Sheet'!C59,0) -> 2891.12 | E53: =IFERROR('Data Sheet'!D59,0) -> 4000.93 | F53: =IFERROR('Data Sheet'!E59,0) -> 3507.57 | G53: =IFERROR('Data Sheet'!F59,0) -> 3382.05 | H53: =IFERROR('Data Sheet'!G59,0) -> 3574.97 | I53: =IFERROR('Data Sheet'!H59,0) -> 1863.97 | J53: =IFERROR('Data Sheet'!I59,0) -> 1704.34 | ... L53: =IFERROR('Data Sheet'!K59,0) -> 3222.2
B54: Other Liabilities | C54: =IFERROR('Data Sheet'!B60,0) -> 2097.18 | D54: =IFERROR('Data Sheet'!C60,0) -> 2520.66 | E54: =IFERROR('Data Sheet'!D60,0) -> 3637.37 | F54: =IFERROR('Data Sheet'!E60,0) -> 4097.89 | G54: =IFERROR('Data Sheet'!F60,0) -> 3444.58 | H54: =IFERROR('Data Sheet'!G60,0) -> 3406.95 | I54: =IFERROR('Data Sheet'!H60,0) -> 2940.92 | J54: =IFERROR('Data Sheet'!I60,0) -> 2821.85 | ... L54: =IFERROR('Data Sheet'!K60,0) -> 2571.31
B55: Total Liabilities | C55: =IFERROR('Data Sheet'!B61,0) -> 9125.02 | D55: =IFERROR('Data Sheet'!C61,0) -> 9678.74 | E55: =IFERROR('Data Sheet'!D61,0) -> 12940.25 | F55: =IFERROR('Data Sheet'!E61,0) -> 13863.77 | G55: =IFERROR('Data Sheet'!F61,0) -> 14093.55 | H55: =IFERROR('Data Sheet'!G61,0) -> 14880.28 | I55: =IFERROR('Data Sheet'!H61,0) -> 14243.79 | J55: =IFERROR('Data Sheet'!I61,0) -> 16082.12 | ... L55: =IFERROR('Data Sheet'!K61,0) -> 18392.08
B57: Fixed Assets Net Block | C57: =IFERROR('Data Sheet'!B62,0) -> 5550.95 | D57: =IFERROR('Data Sheet'!C62,0) -> 5931.41 | E57: =IFERROR('Data Sheet'!D62,0) -> 8082.89 | F57: =IFERROR('Data Sheet'!E62,0) -> 8315 | G57: =IFERROR('Data Sheet'!F62,0) -> 8670.26 | H57: =IFERROR('Data Sheet'!G62,0) -> 9231.4 | I57: =IFERROR('Data Sheet'!H62,0) -> 8904.77 | J57: =IFERROR('Data Sheet'!I62,0) -> 9219.3 | ... L57: =IFERROR('Data Sheet'!K62,0) -> 10440.24
B58: Capital Work in Progress | C58: =IFERROR('Data Sheet'!B63,0) -> 224.61 | D58: =IFERROR('Data Sheet'!C63,0) -> 43.66 | E58: =IFERROR('Data Sheet'!D63,0) -> 97.43 | F58: =IFERROR('Data Sheet'!E63,0) -> 83.88 | G58: =IFERROR('Data Sheet'!F63,0) -> 52.06 | H58: =IFERROR('Data Sheet'!G63,0) -> 57.04 | I58: =IFERROR('Data Sheet'!H63,0) -> 57.43 | J58: =IFERROR('Data Sheet'!I63,0) -> 116.44 | ... L58: =IFERROR('Data Sheet'!K63,0) -> 83.36
B59: Investments | C59: =IFERROR('Data Sheet'!B64,0) -> 185.69 | D59: =IFERROR('Data Sheet'!C64,0) -> 189.5 | E59: =IFERROR('Data Sheet'!D64,0) -> 933.54 | F59: =IFERROR('Data Sheet'!E64,0) -> 997.28 | G59: =IFERROR('Data Sheet'!F64,0) -> 515.98 | H59: =IFERROR('Data Sheet'!G64,0) -> 671.98 | I59: =IFERROR('Data Sheet'!H64,0) -> 679.1 | J59: =IFERROR('Data Sheet'!I64,0) -> 1015.43 | ... L59: =IFERROR('Data Sheet'!K64,0) -> 3503.67
...

Sheet Ratio Analysis
B2: ='Data Sheet'!B1 -> GODREJ CONSUMER PRODUCTS LTD
B3: (GODREJCP | BSE Code: 532424)
B5: ="Ratio Analysis of - "&'[2]Data Sheet'!B1 -> Ratio Analysis of - GODREJ CONSUMER PRODUCTS LTD
B6: Years | C6: ='[2]Data Sheet'!B16 -> 42094 | D6: ='[2]Data Sheet'!C16 -> 42460 | E6: ='[2]Data Sheet'!D16 -> 42825 | F6: ='[2]Data Sheet'!E16 -> 43190 | G6: ='[2]Data Sheet'!F16 -> 43555 | H6: ='[2]Data Sheet'!G16 -> 43921 | I6: ='[2]Data Sheet'!H16 -> 44286 | J6: ='[2]Data Sheet'!I16 -> 44651 | ... L6: ='[2]Data Sheet'!K16 -> 45382 | M6: Trend | N6: Mean | O6: Median
B8: SalesGrowth | C8: - | D8: =IFERROR(HistoricalFS!D10,0) -> 0.018219179 | E8: =IFERROR(HistoricalFS!E10,0) -> 0.10019492 | F8: =IFERROR(HistoricalFS!F10,0) -> 0.06252974 | G8: =IFERROR(HistoricalFS!G10,0) -> 0.047414402 | H8: =IFERROR(HistoricalFS!H10,0) -> -0.039124171 | I8: =IFERROR(HistoricalFS!I10,0) -> 0.11278807 | J8: =IFERROR(HistoricalFS!J10,0) -> 0.11314924 | K8: =IFERROR(HistoricalFS!K10,0) -> 0.084671527 | L8: =IFERROR(HistoricalFS!L10,0) -> 0.058586795 | N8: =IFERROR(AVERAGE(D8:L8),0) -> 0.062047745 | O8: =IFERROR(MEDIAN(C8:L8),0) -> 0.06252974
B9: EBITDA Growth | C9: - | D9: =IFERROR(HistoricalFS!D21/HistoricalFS!C21-1,0) -> 0.2019145 | E9: =IFERROR(HistoricalFS!E21/HistoricalFS!D21-1,0) -> 0.15043623 | F9: =IFERROR(HistoricalFS!F21/HistoricalFS!E21-1,0) -> 0.093191938 | G9: =IFERROR(HistoricalFS!G21/HistoricalFS!F21-1,0) -> 0.022630013 | H9: =IFERROR(HistoricalFS!H21/HistoricalFS!G21-1,0) -> 0.010405476 | I9: =IFERROR(HistoricalFS!I21/HistoricalFS!H21-1,0) -> 0.11399187 | J9: =IFERROR(HistoricalFS!J21/HistoricalFS!I21-1,0) -> 0.0041346082 | K9: =IFERROR(HistoricalFS!K21/HistoricalFS!J21-1,0) -> 0.014120987 | L9: =IFERROR(HistoricalFS!L21/HistoricalFS!K21-1,0) -> 0.21042895 | N9: =IFERROR(AVERAGE(D9:L9),0) -> 0.091250508 | O9: =IFERROR(MEDIAN(C9:L9),0) -> 0.093191938
B10: EBIT Growth | C10: - | D10: =IFERROR(HistoricalFS!D30/HistoricalFS!C30-1,0) -> 0.21518912 | E10: =IFERROR(HistoricalFS!E30/HistoricalFS!D30-1,0) -> 0.12755563 | F10: =IFERROR(HistoricalFS!F30/HistoricalFS!E30-1,0) -> 0.089791738 | G10: =IFERROR(HistoricalFS!G30/HistoricalFS!F30-1,0) -> -0.0183527 | H10: =IFERROR(HistoricalFS!H30/HistoricalFS!G30-1,0) -> 0.0028780652 | I10: =IFERROR(HistoricalFS!I30/HistoricalFS!H30-1,0) -> 0.19059907 | J10: =IFERROR(HistoricalFS!J30/HistoricalFS!I30-1,0) -> 0.0093451131 | K10: =IFERROR(HistoricalFS!K30/HistoricalFS!J30-1,0) -> -0.028194647 | L10: =IFERROR(HistoricalFS!L30/HistoricalFS!K30-1,0) -> 0.19240697 | N10: =IFERROR(AVERAGE(D10:L10),0) -> 0.08680204 | O10: =IFERROR(MEDIAN(C10:L10),0) -> 0.089791738
B11: Net Profit Growth | C11: - | D11: =IFERROR(HistoricalFS!D36/HistoricalFS!C36-1,0) -> 0.20947068 | E11: =IFERROR(HistoricalFS!E36/HistoricalFS!D36-1,0) -> 0.12733147 | F11: =IFERROR(HistoricalFS!F36/HistoricalFS!E36-1,0) -> 0.096696677 | G11: =IFERROR(HistoricalFS!G36/HistoricalFS!F36-1,0) -> 0.46537864 | H11: =IFERROR(HistoricalFS!H36/HistoricalFS!G36-1,0) -> -0.2601865 | I11: =IFERROR(HistoricalFS!I36/HistoricalFS!H36-1,0) -> 0.15957447 | J11: =IFERROR(HistoricalFS!J36/HistoricalFS!I36-1,0) -> 0.0040630778 | K11: =IFERROR(HistoricalFS!K36/HistoricalFS!J36-1,0) -> -0.068593413 | L11: =IFERROR(HistoricalFS!L36/HistoricalFS!K36-1,0) -> 0.03768512 | N11: =IFERROR(AVERAGE(D11:L11),0) -> 0.085713356 | O11: =IFERROR(MEDIAN(C11:L11),0) -> 0.096696677
B12: Dividend Growth | C12: - | D12: =IFERROR(HistoricalFS!D44/HistoricalFS!C44-1,0) -> 0.045570291 | E12: =IFERROR(HistoricalFS!E44/HistoricalFS!D44-1,0) -> 1.6089177 | F12: =IFERROR(HistoricalFS!F44/HistoricalFS!E44-1,0) -> 0.3332681 | G12: =IFERROR(HistoricalFS!G44/HistoricalFS!F44-1,0) -> 0.50007339 | H12: =IFERROR(HistoricalFS!H44/HistoricalFS!G44-1,0) -> -0.2 | I12: =IFERROR(HistoricalFS!I44/HistoricalFS!H44-1,0) -> -1 | J12: =IFERROR(HistoricalFS!J44/HistoricalFS!I44-1,0) -> 0 | K12: =IFERROR(HistoricalFS!K44/HistoricalFS!J44-1,0) -> 0 | L12: =IFERROR(HistoricalFS!L44/HistoricalFS!K44-1,0) -> 0 | N12: =IFERROR(AVERAGE(D12:L12),0) -> 0.14309217 | O12: =IFERROR(MEDIAN(C12:L12),0) -> 0
B14: Gross Margin | C14: =IFERROR(HistoricalFS!C16,0) -> 0.40139367 | D14: =IFERROR(HistoricalFS!D16,0) -> 0.38774175 | E14: =IFERROR(HistoricalFS!E16,0) -> 0.40516794 | F14: =IFERROR(HistoricalFS!F16,0) -> 0.41592578 | G14: =IFERROR(HistoricalFS!G16,0) -> 0.41132152 | H14: =IFERROR(HistoricalFS!H16,0) -> 0.4170521 | I14: =IFERROR(HistoricalFS!I16,0) -> 0.4055249 | J14: =IFERROR(HistoricalFS!J16,0) -> 0.36928115 | ... L14: =IFERROR(HistoricalFS!L16,0) -> 0.42247045 | N14: =IFERROR(AVERAGE(C14:L14),0) -> 0.40044713 | O14: =IFERROR(MEDIAN(C14:L14),0) -> 0.40534642
B15: EBITDA Margin | C15: =IFERROR(HistoricalFS!C22,0) -> 0.16667775 | D15: =IFERROR(HistoricalFS!D22,0) -> 0.19674782 | E15: =IFERROR(HistoricalFS!E22,0) -> 0.20573247 | F15: =IFERROR(HistoricalFS!F22,0) -> 0.21166944 | G15: =IFERROR(HistoricalFS!G22,0) -> 0.20666082 | H15: =IFERROR(HistoricalFS!H22,0) -> 0.21731344 | I15: =IFERROR(HistoricalFS!I22,0) -> 0.21754852 | J15: =IFERROR(HistoricalFS!J22,0) -> 0.19624323 | ... L15: =IFERROR(HistoricalFS!L22,0) -> 0.20979689 | N15: =IFERROR(AVERAGE(C15:L15),0) -> 0.20118693 | O15: =IFERROR(MEDIAN(C15:L15),0) -> 0.20619665
B16: EBIT Margin | C16: =IFERROR((HistoricalFS!C21-HistoricalFS!C27)/HistoricalFS!C9,0) -> 0.1557049 | D16: =IFERROR((HistoricalFS!D21-HistoricalFS!D27)/HistoricalFS!D9,0) -> 0.18480202 | E16: =IFERROR((HistoricalFS!E21-HistoricalFS!E27)/HistoricalFS!E9,0) -> 0.19045718 | F16: =IFERROR((HistoricalFS!F21-HistoricalFS!F27)/HistoricalFS!F9,0) -> 0.19586024 | G16: =IFERROR((HistoricalFS!G21-HistoricalFS!G27)/HistoricalFS!G9,0) -> 0.19018086 | H16: =IFERROR((HistoricalFS!H21-HistoricalFS!H27)/HistoricalFS!H9,0) -> 0.19740788 | I16: =IFERROR((HistoricalFS!I21-HistoricalFS!I27)/HistoricalFS!I9,0) -> 0.1990648 | J16: =IFERROR((HistoricalFS!J21-HistoricalFS!J27)/HistoricalFS!J9,0) -> 0.17914308 | ... L16: =IFERROR((HistoricalFS!L21-HistoricalFS!L27)/HistoricalFS!L9,0) -> 0.19270281 | N16: =IFERROR(AVERAGE(C16:L16),0) -> 0.18510578 | O16: =IFERROR(MEDIAN(C16:L16),0) -> 0.19031902
B17: EBT Margin | C17: =IFERROR(HistoricalFS!C31,0) -> 0.14211153 | D17: =IFERROR(HistoricalFS!D31,0) -> 0.16960237 | E17: =IFERROR(HistoricalFS!E31,0) -> 0.1738202 | F17: =IFERROR(HistoricalFS!F31,0) -> 0.17828002 | G17: =IFERROR(HistoricalFS!G31,0) -> 0.16708582 | H17: =IFERROR(HistoricalFS!H31,0) -> 0.17438955 | I17: =IFERROR(HistoricalFS!I31,0) -> 0.18658363 | J17: =IFERROR(HistoricalFS!J31,0) -> 0.16918421 | ... L17: =IFERROR(HistoricalFS!L31,0) -> 0.17074143 | N17: =IFERROR(AVERAGE(C17:L17),0) -> 0.16833784 | O17: =IFERROR(MEDIAN(C17:L17),0) -> 0.1701719
B18: Net Profit Margin | C18: =IFERROR(HistoricalFS!C37,0) -> 0.10919904 | D18: =IFERROR(HistoricalFS!D37,0) -> 0.12970982 | E18: =IFERROR(HistoricalFS!E37,0) -> 0.13290915 | F18: =IFERROR(HistoricalFS!F37,0) -> 0.137183 | G18: =IFERROR(HistoricalFS!G37,0) -> 0.19192503 | H18: =IFERROR(HistoricalFS!H37,0) -> 0.14777011 | I18: =IFERROR(HistoricalFS!I37,0) -> 0.153983 | J18: =IFERROR(HistoricalFS!J37,0) -> 0.13889301 | ... L18: =IFERROR(HistoricalFS!L37,0) -> 0.1169124 | N18: =IFERROR(AVERAGE(C18:L18),0) -> 0.13777519 | O18: =IFERROR(MEDIAN(C18:L18),0) -> 0.13504607
B20: SalesExpenses%Sales | C20: =IFERROR(HistoricalFS!C19,0) -> 0.23471592 | D20: =IFERROR(HistoricalFS!D19,0) -> 0.19099394 | E20: =IFERROR(HistoricalFS!E19,0) -> 0.19943547 | F20: =IFERROR(HistoricalFS!F19,0) -> 0.20425634 | G20: =IFERROR(HistoricalFS!G19,0) -> 0.2046607 | H20: =IFERROR(HistoricalFS!H19,0) -> 0.19973867 | I20: =IFERROR(HistoricalFS!I19,0) -> 0.18797637 | J20: =IFERROR(HistoricalFS!J19,0) -> 0.17303792 | ... L20: =IFERROR(HistoricalFS!L19,0) -> 0.21267357 | N20: =IFERROR(AVERAGE(C20:L20),0) -> 0.1992602 | O20: =IFERROR(MEDIAN(C20:L20),0) -> 0.19958707
B21: Depreciation%Sales | C21: =IFERROR(HistoricalFS!C28,0) -> 0.010972846 | D21: =IFERROR(HistoricalFS!D28,0) -> 0.011945802 | E21: =IFERROR(HistoricalFS!E28,0) -> 0.015275289 | F21: =IFERROR(HistoricalFS!F28,0) -> 0.015809201 | G21: =IFERROR(HistoricalFS!G28,0) -> 0.016479969 | H21: =IFERROR(HistoricalFS!H28,0) -> 0.019905558 | I21: =IFERROR(HistoricalFS!I28,0) -> 0.018483727 | J21: =IFERROR(HistoricalFS!J28,0) -> 0.017100151 | ... L21: =IFERROR(HistoricalFS!L28,0) -> 0.017094078 | N21: =IFERROR(AVERAGE(C21:L21),0) -> 0.016081148 | O21: =IFERROR(MEDIAN(C21:L21),0) -> 0.016787023
B22: OperatingIncome%Sales | C22: =C16 -> 0.1557049 | D22: =D16 -> 0.18480202 | E22: =E16 -> 0.19045718 | F22: =F16 -> 0.19586024 | G22: =G16 -> 0.19018086 | H22: =H16 -> 0.19740788 | I22: =I16 -> 0.1990648 | J22: =J16 -> 0.17914308 | ... L22: =L16 -> 0.19270281 | N22: =IFERROR(AVERAGE(C22:L22),0) -> 0.18510578 | O22: =IFERROR(MEDIAN(C22:L22),0) -> 0.19031902
B24: Return on Capital Employed | C24: =IFERROR((HistoricalFS!C21-HistoricalFS!C27)/SUM(HistoricalFS!C51:C53),0) -> 0.18329529 | D24: =IFERROR((HistoricalFS!D21-HistoricalFS!D27)/SUM(HistoricalFS!D51:D53),0) -> 0.2174815 | E24: =IFERROR((HistoricalFS!E21-HistoricalFS!E27)/SUM(HistoricalFS!E51:E53),0) -> 0.18974124 | F24: =IFERROR((HistoricalFS!F21-HistoricalFS!F27)/SUM(HistoricalFS!F51:F53),0) -> 0.19749577 | G24: =IFERROR((HistoricalFS!G21-HistoricalFS!G27)/SUM(HistoricalFS!G51:G53),0) -> 0.18420467 | H24: =IFERROR((HistoricalFS!H21-HistoricalFS!H27)/SUM(HistoricalFS!H51:H53),0) -> 0.17052329 | I24: =IFERROR((HistoricalFS!I21-HistoricalFS!I27)/SUM(HistoricalFS!I51:I53),0) -> 0.19423474 | J24: =IFERROR((HistoricalFS!J21-HistoricalFS!J27)/SUM(HistoricalFS!J51:J53),0) -> 0.16585258 | ... L24: =IFERROR((HistoricalFS!L21-HistoricalFS!L27)/SUM(HistoricalFS!L51:L53),0) -> 0.17169582 | N24: =IFERROR(AVERAGE(C24:L24),0) -> 0.18224034 | O24: =IFERROR(MEDIAN(C24:L24),0) -> 0.18374998
B25: Retained Earnings% | C25: =IFERROR(HistoricalFS!C47,0) -> 0.79276527 | D25: =IFERROR(HistoricalFS!D47,0) -> 0.82081343 | E25: =IFERROR(HistoricalFS!E47,0) -> 0.58523774 | F25: =IFERROR(HistoricalFS!F47,0) -> 0.49566955 | G25: =IFERROR(HistoricalFS!G47,0) -> 0.48362784 | H25: =IFERROR(HistoricalFS!H47,0) -> 0.44156447 | I25: =IFERROR(HistoricalFS!I47,0) -> 1 | J25: =IFERROR(HistoricalFS!J47,0) -> 1 | ... L25: =IFERROR(HistoricalFS!L47,0) -> 1 | N25: =IFERROR(AVERAGE(C25:L25),0) -> 0.76196783 | O25: =IFERROR(MEDIAN(C25:L25),0) -> 0.80678935
B26: Return on Equity% | C26: =IFERROR(HistoricalFS!C36/(SUM(HistoricalFS!C51:C52)),0) -> 0.20957666 | D26: =IFERROR(HistoricalFS!D36/(SUM(HistoricalFS!D51:D52)),0) -> 0.25607458 | E26: =IFERROR(HistoricalFS!E36/(SUM(HistoricalFS!E51:E52)),0) -> 0.23232773 | F26: =IFERROR(HistoricalFS!F36/(SUM(HistoricalFS!F51:F52)),0) -> 0.215857 | G26: =IFERROR(HistoricalFS!G36/(SUM(HistoricalFS!G51:G52)),0) -> 0.27240977 | H26: =IFERROR(HistoricalFS!H36/(SUM(HistoricalFS!H51:H52)),0) -> 0.18542077 | I26: =IFERROR(HistoricalFS!I36/(SUM(HistoricalFS!I51:I52)),0) -> 0.17991715 | J26: =IFERROR(HistoricalFS!J36/(SUM(HistoricalFS!J51:J52)),0) -> 0.14755368 | ... L26: =IFERROR(HistoricalFS!L36/(SUM(HistoricalFS!L51:L52)),0) -> 0.13080929 | N26: =IFERROR(AVERAGE(C26:L26),0) -> 0.19450788 | O26: =IFERROR(MEDIAN(C26:L26),0) -> 0.19749871
B27: Self Sustained Growth Rate | C27: =IFERROR(C25*C26,0) -> 0.1661451 | D27: =IFERROR(D25*D26,0) -> 0.21018946 | E27: =IFERROR(E25*E26,0) -> 0.13596696 | F27: =IFERROR(F25*F26,0) -> 0.10699374 | G27: =IFERROR(G25*G26,0) -> 0.13174495 | H27: =IFERROR(H25*H26,0) -> 0.081875225 | I27: =IFERROR(I25*I26,0) -> 0.17991715 | J27: =IFERROR(J25*J26,0) -> 0.14755368 | ... L27: =IFERROR(L25*L26,0) -> 0.13080929 | N27: =IFERROR(AVERAGE(C27:L27),0) -> 0.14063277 | O27: =IFERROR(MEDIAN(C27:L27),0) -> 0.13385595
B28: Interest Coverage Ratio | C28: =IFERROR((HistoricalFS!C21-HistoricalFS!C27)/HistoricalFS!C24,0) -> 11.454473 | D28: =IFERROR((HistoricalFS!D21-HistoricalFS!D27)/HistoricalFS!D24,0) -> 12.15831 | E28: =IFERROR((HistoricalFS!E21-HistoricalFS!E27)/HistoricalFS!E24,0) -> 11.447824 | F28: =IFERROR((HistoricalFS!F21-HistoricalFS!F27)/HistoricalFS!F24,0) -> 11.140943 | G28: =IFERROR((HistoricalFS!G21-HistoricalFS!G27)/HistoricalFS!G24,0) -> 8.2347089 | H28: =IFERROR((HistoricalFS!H21-HistoricalFS!H27)/HistoricalFS!H24,0) -> 8.5761189 | I28: =IFERROR((HistoricalFS!I21-HistoricalFS!I27)/HistoricalFS!I24,0) -> 15.949219 | J28: =IFERROR((HistoricalFS!J21-HistoricalFS!J27)/HistoricalFS!J24,0) -> 17.988304 | ... L28: =IFERROR((HistoricalFS!L21-HistoricalFS!L27)/HistoricalFS!L24,0) -> 8.7746229 | N28: =IFERROR(AVERAGE(C28:L28),0) -> 11.743351 | O28: =IFERROR(MEDIAN(C28:L28),0) -> 11.451148
B30: Debtor Turnover Ratio | C30: =IFERROR(HistoricalFS!C9/HistoricalFS!C63,0) -> 10.28257 | D30: =IFERROR(HistoricalFS!D9/HistoricalFS!D63,0) -> 7.534709 | E30: =IFERROR(HistoricalFS!E9/HistoricalFS!E63,0) -> 9.0089916 | F30: =IFERROR(HistoricalFS!F9/HistoricalFS!F63,0) -> 7.9064071 | G30: =IFERROR(HistoricalFS!G9/HistoricalFS!G63,0) -> 7.9776781 | H30: =IFERROR(HistoricalFS!H9/HistoricalFS!H63,0) -> 8.5640959 | I30: =IFERROR(HistoricalFS!I9/HistoricalFS!I63,0) -> 10.979214 | J30: =IFERROR(HistoricalFS!J9/HistoricalFS!J63,0) -> 10.997295 | ... L30: =IFERROR(HistoricalFS!L9/HistoricalFS!L63,0) -> 9.1809206 | N30: =IFERROR(AVERAGE(C30:L30),0) -> 9.3125034 | O30: =IFERROR(MEDIAN(C30:L30),0) -> 9.0949561
B31: Creditor Turnover Ratio | C31: =IFERROR(HistoricalFS!C9/HistoricalFS!C54,0) -> 3.9448927 | D31: =IFERROR(HistoricalFS!D9/HistoricalFS!D54,0) -> 3.3419343 | E31: =IFERROR(HistoricalFS!E9/HistoricalFS!E54,0) -> 2.5479701 | F31: =IFERROR(HistoricalFS!F9/HistoricalFS!F54,0) -> 2.4030489 | G31: =IFERROR(HistoricalFS!G9/HistoricalFS!G54,0) -> 2.994368 | H31: =IFERROR(HistoricalFS!H9/HistoricalFS!H54,0) -> 2.9089948 | I31: =IFERROR(HistoricalFS!I9/HistoricalFS!I54,0) -> 3.7500578 | J31: =IFERROR(HistoricalFS!J9/HistoricalFS!J54,0) -> 4.3505147 | ... L31: =IFERROR(HistoricalFS!L9/HistoricalFS!L54,0) -> 5.4820733 | N31: =IFERROR(AVERAGE(C31:L31),0) -> 3.702174 | O31: =IFERROR(MEDIAN(C31:L31),0) -> 3.545996
B32: Inventory Turnover | C32: =IFERROR(HistoricalFS!C9/HistoricalFS!C64,0) -> 7.719579 | D32: =IFERROR(HistoricalFS!D9/HistoricalFS!D64,0) -> 6.4453014 | E32: =IFERROR(HistoricalFS!E9/HistoricalFS!E64,0) -> 6.5613522 | F32: =IFERROR(HistoricalFS!F9/HistoricalFS!F64,0) -> 6.2415574 | G32: =IFERROR(HistoricalFS!G9/HistoricalFS!G64,0) -> 6.6177378 | H32: =IFERROR(HistoricalFS!H9/HistoricalFS!H64,0) -> 5.8192024 | I32: =IFERROR(HistoricalFS!I9/HistoricalFS!I64,0) -> 6.4259985 | J32: =IFERROR(HistoricalFS!J9/HistoricalFS!J64,0) -> 5.7640209 | ... L32: =IFERROR(HistoricalFS!L9/HistoricalFS!L64,0) -> 11.091265 | N32: =IFERROR(AVERAGE(C32:L32),0) -> 7.134878 | O32: =IFERROR(MEDIAN(C32:L32),0) -> 6.5033268
B33: Fixed Asset Turnover | C33: =IFERROR(HistoricalFS!C9/HistoricalFS!C57,0) -> 1.4904025 | D33: =IFERROR(HistoricalFS!D9/HistoricalFS!D57,0) -> 1.4202154 | E33: =IFERROR(HistoricalFS!E9/HistoricalFS!E57,0) -> 1.1466085 | F33: =IFERROR(HistoricalFS!F9/HistoricalFS!F57,0) -> 1.1842971 | G33: =IFERROR(HistoricalFS!G9/HistoricalFS!G57,0) -> 1.1896229 | H33: =IFERROR(HistoricalFS!H9/HistoricalFS!H57,0) -> 1.0735966 | I33: =IFERROR(HistoricalFS!I9/HistoricalFS!I57,0) -> 1.238507 | J33: =IFERROR(HistoricalFS!J9/HistoricalFS!J57,0) -> 1.3316087 | ... L33: =IFERROR(HistoricalFS!L9/HistoricalFS!L57,0) -> 1.3501711 | N33: =IFERROR(AVERAGE(C33:L33),0) -> 1.276552 | O33: =IFERROR(MEDIAN(C33:L33),0) -> 1.2850578
B34: Capital Turnover Ratio | C34: =IFERROR(HistoricalFS!C9/(SUM(HistoricalFS!C51:C52)),0) -> 1.9192171 | D34: =IFERROR(HistoricalFS!D9/(SUM(HistoricalFS!D51:D52)),0) -> 1.9742111 | E34: =IFERROR(HistoricalFS!E9/(SUM(HistoricalFS!E51:E52)),0) -> 1.7480191 | F34: =IFERROR(HistoricalFS!F9/(SUM(HistoricalFS!F51:F52)),0) -> 1.5734967 | G34: =IFERROR(HistoricalFS!G9/(SUM(HistoricalFS!G51:G52)),0) -> 1.4193551 | H34: =IFERROR(HistoricalFS!H9/(SUM(HistoricalFS!H51:H52)),0) -> 1.2547921 | I34: =IFERROR(HistoricalFS!I9/(SUM(HistoricalFS!I51:I52)),0) -> 1.1684222 | J34: =IFERROR(HistoricalFS!J9/(SUM(HistoricalFS!J51:J52)),0) -> 1.062355 | ... L34: =IFERROR(HistoricalFS!L9/(SUM(HistoricalFS!L51:L52)),0) -> 1.1188659 | N34: =IFERROR(AVERAGE(C34:L34),0) -> 1.4204063 | O34: =IFERROR(MEDIAN(C34:L34),0) -> 1.3370736
B36: Debtor Days | C36: =IFERROR(365/C30,0) -> 35.496963 | D36: =IFERROR(365/D30,0) -> 48.442481 | E36: =IFERROR(365/E30,0) -> 40.515078 | F36: =IFERROR(365/F30,0) -> 46.165091 | G36: =IFERROR(365/G30,0) -> 45.752661 | H36: =IFERROR(365/H30,0) -> 42.619794 | I36: =IFERROR(365/I30,0) -> 33.24464 | J36: =IFERROR(365/J30,0) -> 33.189981 | ... L36: =IFERROR(365/L30,0) -> 39.756362 | N36: =IFERROR(AVERAGE(C36:L36),0) -> 39.931704 | O36: =IFERROR(MEDIAN(C36:L36),0) -> 40.13572
B37: Payable Days | C37: =IFERROR(365/C31,0) -> 92.524697 | D37: =IFERROR(365/D31,0) -> 109.21819 | E37: =IFERROR(365/E31,0) -> 143.25129 | F37: =IFERROR(365/F31,0) -> 151.89038 | G37: =IFERROR(365/G31,0) -> 121.89551 | H37: =IFERROR(365/H31,0) -> 125.47289 | I37: =IFERROR(365/I31,0) -> 97.331833 | J37: =IFERROR(365/J31,0) -> 83.898118 | ... L37: =IFERROR(365/L31,0) -> 66.580649 | N37: =IFERROR(AVERAGE(C37:L37),0) -> 106.0959 | O37: =IFERROR(MEDIAN(C37:L37),0) -> 103.27501
B38: Inventory Days | C38: =IFERROR(365/C32,0) -> 47.282371 | D38: =IFERROR(365/D32,0) -> 56.630401 | E38: =IFERROR(365/E32,0) -> 55.628777 | F38: =IFERROR(365/F32,0) -> 58.478994 | G38: =IFERROR(365/G32,0) -> 55.154799 | H38: =IFERROR(365/H32,0) -> 62.723372 | I38: =IFERROR(365/I32,0) -> 56.800511 | J38: =IFERROR(365/J32,0) -> 63.32385 | ... L38: =IFERROR(365/L32,0) -> 32.908781 | N38: =IFERROR(AVERAGE(C38:L38),0) -> 53.106621 | O38: =IFERROR(MEDIAN(C38:L38),0) -> 56.129589
B39: Cash Conversion Cycle (in days) | C39: =IFERROR(SUM(C36,C38)-C37,0) -> -9.745363 | D39: =IFERROR(SUM(D36,D38)-D37,0) -> -4.1453048 | E39: =IFERROR(SUM(E36,E38)-E37,0) -> -47.107433 | F39: =IFERROR(SUM(F36,F38)-F37,0) -> -47.246292 | G39: =IFERROR(SUM(G36,G38)-G37,0) -> -20.988047 | H39: =IFERROR(SUM(H36,H38)-H37,0) -> -20.129727 | I39: =IFERROR(SUM(I36,I38)-I37,0) -> -7.2866823 | J39: =IFERROR(SUM(J36,J38)-J37,0) -> 12.615713 | ... L39: =IFERROR(SUM(L36,L38)-L37,0) -> 6.0844942 | N39: =IFERROR(AVERAGE(C39:L39),0) -> -13.057571 | O39: =IFERROR(MEDIAN(C39:L39),0) -> -8.5160226
B41: CFO/Sales | C41: =IFERROR(HistoricalFS!C82/HistoricalFS!C9,0) -> 0.11688414 | D41: =IFERROR(HistoricalFS!D82/HistoricalFS!D9,0) -> 0.047840188 | E41: =IFERROR(HistoricalFS!E82/HistoricalFS!E9,0) -> 0.23964411 | F41: =IFERROR(HistoricalFS!F82/HistoricalFS!F9,0) -> 0.17496951 | G41: =IFERROR(HistoricalFS!G82/HistoricalFS!G9,0) -> 0.16937584 | H41: =IFERROR(HistoricalFS!H82/HistoricalFS!H9,0) -> 0.13470154 | I41: =IFERROR(HistoricalFS!I82/HistoricalFS!I9,0) -> 0.17998625 | J41: =IFERROR(HistoricalFS!J82/HistoricalFS!J9,0) -> 0.074451187 | ... L41: =IFERROR(HistoricalFS!L82/HistoricalFS!L9,0) -> 0.11449967 | N41: =IFERROR(AVERAGE(C41:L41),0) -> 0.1420947 | O41: =IFERROR(MEDIAN(C41:L41),0) -> 0.15164804
B42: CFO/Total Assets | C42: =IFERROR(HistoricalFS!C82/HistoricalFS!C68,0) -> 0.10597237 | D42: =IFERROR(HistoricalFS!D82/HistoricalFS!D68,0) -> 0.041637651 | E42: =IFERROR(HistoricalFS!E82/HistoricalFS!E68,0) -> 0.17163501 | F42: =IFERROR(HistoricalFS!F82/HistoricalFS!F68,0) -> 0.12428077 | G42: =IFERROR(HistoricalFS!G82/HistoricalFS!G68,0) -> 0.12395741 | H42: =IFERROR(HistoricalFS!H82/HistoricalFS!H68,0) -> 0.089716054 | I42: =IFERROR(HistoricalFS!I82/HistoricalFS!I68,0) -> 0.13935898 | J42: =IFERROR(HistoricalFS!J82/HistoricalFS!J68,0) -> 0.056833303 | ... L42: =IFERROR(HistoricalFS!L82/HistoricalFS!L68,0) -> 0.087755164 | N42: =IFERROR(AVERAGE(C42:L42),0) -> 0.1069894 | O42: =IFERROR(MEDIAN(C42:L42),0) -> 0.11496489
B43: CFO/Total Debt | C43: =IFERROR(HistoricalFS!C82/HistoricalFS!C53,0) -> 0.3558876 | D43: =IFERROR(HistoricalFS!D82/HistoricalFS!D53,0) -> 0.13939235 | E43: =IFERROR(HistoricalFS!E82/HistoricalFS!E53,0) -> 0.55512093 | F43: =IFERROR(HistoricalFS!F82/HistoricalFS!F53,0) -> 0.49122327 | G43: =IFERROR(HistoricalFS!G82/HistoricalFS!G53,0) -> 0.51655061 | H43: =IFERROR(HistoricalFS!H82/HistoricalFS!H53,0) -> 0.37342971 | I43: =IFERROR(HistoricalFS!I82/HistoricalFS!I53,0) -> 1.0649313 | J43: =IFERROR(HistoricalFS!J82/HistoricalFS!J53,0) -> 0.53627797 | ... L43: =IFERROR(HistoricalFS!L82/HistoricalFS!L53,0) -> 0.50090001 | N43: =IFERROR(AVERAGE(C43:L43),0) -> 0.65211781 | O43: =IFERROR(MEDIAN(C43:L43),0) -> 0.50872531

Sheet Common Size Statement
B2: ='Data Sheet'!B1 -> GODREJ CONSUMER PRODUCTS LTD
B3: (GODREJCP | BSE Code: 532424)
B5: Common Size Income Statement - GODREJ CONSUMER PRODUCTS LTD
B7: Particulars | C7: 42094 | D7: 42460 | E7: 42825 | F7: 43190 | G7: 43555 | H7: 43921 | I7: 44286 | J7: 44651 | K7: 45016 | L7: 45382
B9: Sales | C9: 1 | D9: 1 | E9: 1 | F9: 1 | G9: 1 | H9: 1 | I9: 1 | J9: 1 | K9: 1 | L9: 1
B10: Raw Material Cost | C10: 0.46010045 | D10: 0.46999008 | E10: 0.46028177 | F10: 0.42837167 | G10: 0.42657019 | H10: 0.44747447 | I10: 0.45080618 | J10: 0.49986804 | K10: 0.48737343 | L10: 0.44930339
B11: Change in Inventory | C11: -0.004235388 | D11: 0.010909462 | E11: 0.014386199 | F11: -0.0056867629 | G11: -0.014983024 | H11: 0.01747084 | I11: 0.003840009 | J11: 0.0050128294 | K11: -0.015991325 | L11: 0.00093146265
B12: Power and Fuel | C12: 0.013286354 | D12: 0.013056929 | E12: 0.0096051861 | F12: 0.010267654 | G12: 0.011565452 | H12: 0.011935464 | I12: 0.0096322115 | J12: 0.01087362 | K12: 0.011612372 | L12: 0.010701534
B13: Other Mfr. Exp | C13: 0.027071913 | D13: 0.028042897 | E13: 0.03267727 | F13: 0.032368852 | G13: 0.031974901 | H13: 0.038209832 | I13: 0.036019919 | J13: 0.035050707 | K13: 0.032961174 | L13: 0.029825959
B14: Employee Cost | C14: 0.093912234 | D14: 0.11207781 | E14: 0.10665404 | F14: 0.10737929 | G14: 0.10358491 | H14: 0.10279897 | I14: 0.10185681 | J14: 0.089939315 | K14: 0.083469698 | L14: 0.088630126
B15: Selling and admin | C15: 0.21984975 | D15: 0.17390799 | E15: 0.17796785 | F15: 0.18032725 | G15: 0.18312951 | H15: 0.17860617 | I15: 0.16400329 | J15: 0.14959394 | K15: 0.16104272 | L15: 0.18726159
B16: Other Expenses | C16: 0.014866163 | D16: 0.017085951 | E16: 0.021467623 | F16: 0.023929086 | G16: 0.021531189 | H16: 0.021132502 | I16: 0.023973081 | J16: 0.023443978 | K16: 0.024070346 | L16: 0.025411975
B17: Other Income | C17: 0.0088249337 | D17: -0.031106806 | E17: 0.0082197604 | F17: 0.028766897 | G17: 0.035091921 | H17: 0.0032348549 | I17: 0.0020492138 | J17: 0.0063755957 | K17: 0.0085836781 | L17: -0.15667869
B18: Depreciation | C18: 0.010972846 | D18: 0.011945802 | E18: 0.015275289 | F18: 0.015809201 | G18: 0.016479969 | H18: 0.019905558 | I18: 0.018483727 | J18: 0.017100151 | K18: 0.017744858 | L18: 0.017094078
B19: Interest | C19: 0.013593371 | D19: 0.015199647 | E19: 0.016636976 | F19: 0.017580221 | G19: 0.023095031 | H19: 0.023018323 | I19: 0.012481163 | J19: 0.0099588645 | K19: 0.014154433 | L19: 0.021961378
... B24: EBITDA | C24: 0.16712498 | D24: 0.16528369 | E24: 0.2135325 | F24: 0.24043634 | G24: 0.24175274 | H24: 0.22054829 | I24: 0.21959774 | J24: 0.20261882 | K24: 0.19206261 | L24: 0.053118201
B26: Common Size Balance Sheet - GODREJ CONSUMER PRODUCTS LTD
B28: Particulars | C28: 42094 | D28: 42460 | E28: 42825 | F28: 43190 | G28: 43555 | H28: 43921 | I28: 44286 | J28: 44651 | K28: 45016 | L28: 45382
B30: Total Liabilities | C30: 1 | D30: 1 | E30: 1 | F30: 1 | G30: 1 | H30: 1 | I30: 1 | J30: 1 | K30: 1 | L30: 1
B31: Equity Share Capital | C31: 0.0037304028 | D31: 0.0035180199 | E31: 0.0026320975 | F31: 0.0049142477 | G31: 0.0072529632 | H31: 0.0068701664 | I31: 0.0071785669 | J31: 0.0063586144 | K31: 0.005865027 | L31: 0.0055610893
B32: Reserves | C32: 0.46867295 | D32: 0.43734102 | E32: 0.40709337 | F32: 0.44650048 | G32: 0.5083673 | H32: 0.52392361 | I32: 0.65548916 | J32: 0.71219901 | K32: 0.78521281 | L32: 0.67943865
B33: Borrowings | C33: 0.29776921 | D33: 0.2987083 | E33: 0.30918491 | F33: 0.25300261 | G33: 0.23997148 | H33: 0.24024884 | I33: 0.13086194 | J33: 0.10597732 | K33: 0.064779673 | L33: 0.17519498
B34: Other Liabilities | C34: 0.22982744 | D34: 0.26043266 | E34: 0.28108962 | F34: 0.29558266 | G34: 0.24440826 | H34: 0.22895739 | I34: 0.20647033 | J34: 0.17546505 | K34: 0.14414249 | L34: 0.13980529
B36: Total Assets | C36: 1 | D36: 1 | E36: 1 | F36: 1 | G36: 1 | H36: 1 | I36: 1 | J36: 1 | K36: 1 | L36: 1
B37: Net Block | C37: 0.60832195 | D37: 0.61282874 | E37: 0.62463167 | F37: 0.59976471 | G37: 0.61519348 | H37: 0.62037811 | I37: 0.62516858 | J37: 0.57326397 | K37: 0.5696801 | L37: 0.56764868
B38: Capital Work in Progress | C38: 0.024614741 | D38: 0.0045109177 | E38: 0.0075292208 | F38: 0.0060503023 | G38: 0.0036938883 | H38: 0.0038332612 | I38: 0.0040319325 | J38: 0.007240339 | K38: 0.002604767 | L38: 0.0045323857
B39: Investments | C39: 0.020349544 | D39: 0.019578995 | E39: 0.072142347 | F39: 0.071934257 | G39: 0.036611074 | H39: 0.045159096 | I39: 0.047676917 | J39: 0.063140307 | K39: 0.17370734 | L39: 0.19049885
B40: Other Assets | C40: 0.043096892 | D40: 0.034652238 | E40: 0.036513205 | F40: 0.049350213 | G40: 0.078691316 | H40: 0.086646891 | I40: 0.084916304 | J40: 0.085623662 | K40: 0.072032533 | L40: 0.055000848
B41: Receivables | C41: 0.088172957 | D41: 0.11551194 | E41: 0.079499237 | F41: 0.089838478 | G41: 0.091737 | H41: 0.077770714 | I41: 0.070521961 | J41: 0.069413734 | K41: 0.07141489 | L41: 0.083479954
... B43: Cash & Bank | C43: 0.097996498 | D43: 0.077881005 | E43: 0.070528776 | F43: 0.069260382 | G43: 0.06348436 | H43: 0.051757091 | I43: 0.047193198 | J43: 0.068882088 | K43: 0.02240719 | L43: 0.0297378

Sheet Forcasting
B2: ='Data Sheet'!B1 -> GODREJ CONSUMER PRODUCTS LTD
B3: (GODREJCP | BSE Code: 532424)
B5: Forecasting - GODREJ CONSUMER PRODUCTS LTD
B7: ='Data Sheet'!$B$1&" - "&'Data Sheet'!A17&" Forecasting" -> GODREJ CONSUMER PRODUCTS LTD - Sales Forecasting | G7: ='Data Sheet'!$B$1&" - "&'Data Sheet'!A34&" Forecasting" -> GODREJ CONSUMER PRODUCTS LTD - EBITDA Forecasting | L7: ='Data Sheet'!$B$1&" - "&" EPS Forecasting" -> GODREJ CONSUMER PRODUCTS LTD - EPS Forecasting
B8: Year Weight | C8: Year | D8: Sales | E8: Sales Growth | G8: Year Weight | H8: Year | I8: EBITDA | J8: EBITDA Growth | L8: Year Weight | M8: Year | N8: EPS | O8: EPS Growth
B9: 1 | C9: ='Data Sheet'!$B$16 -> 42094 | D9: {=TRANSPOSE('Data Sheet'!B17:K17)} -> 8273.15 | E9: - | G9: 1 | H9: ='Data Sheet'!$B$16 -> 42094 | I9: {=TRANSPOSE(HistoricalFS!C21:L21)} -> 1378.95 | J9: - | L9: 1 | M9: ='Data Sheet'!$B$16 -> 42094 | N9: {=TRANSPOSE(HistoricalFS!C41:L41)} -> 8.8449187
B10: =B9+1 -> 2 | C10: =C9+365 -> 42459 | D10: 8423.88 | E10: =D10/D9-1 -> 0.018219179 | G10: =G9+1 -> 2 | H10: =H9+365 -> 42459 | I10: 1657.38 | J10: =I10/I9-1 -> 0.2019145 | L10: =L9+1 -> 2 | M10: =M9+365 -> 42459 | N10: 10.695576 | O10: =N10/N9-1 -> 0.2092339
B11: =B10+1 -> 3 | C11: =C10+365 -> 42824 | D11: 9267.91 | E11: =D11/D10-1 -> 0.10019492 | G11: =G10+1 -> 3 | H11: =H10+365 -> 42824 | I11: 1906.71 | J11: =I11/I10-1 -> 0.15043623 | L11: =L10+1 -> 3 | M11: =M10+365 -> 42824 | N11: 12.055099 | O11: =N11/N10-1 -> 0.12711081
B12: =B11+1 -> 4 | C12: =C11+365 -> 43189 | D12: 9847.43 | E12: =D12/D11-1 -> 0.06252974 | G12: =G11+1 -> 4 | H12: =H11+365 -> 43189 | I12: 2084.4 | J12: =I12/I11-1 -> 0.093191938 | L12: =L11+1 -> 4 | M12: =M11+365 -> 43189 | N12: 13.2182 | O12: =N12/N11-1 -> 0.096482059
B13: =B12+1 -> 5 | C13: =C12+365 -> 43554 | D13: 10314.34 | E13: =D13/D12-1 -> 0.047414402 | G13: =G12+1 -> 5 | H13: =H12+365 -> 43554 | I13: 2131.57 | J13: =I13/I12-1 -> 0.022630013 | L13: =L12+1 -> 5 | M13: =M12+365 -> 43554 | N13: 19.365878 | O13: =N13/N12-1 -> 0.46509193
B14: =B13+1 -> 6 | C14: =C13+365 -> 43919 | D14: 9910.8 | E14: =D14/D13-1 -> -0.039124171 | G14: =G13+1 -> 6 | H14: =H13+365 -> 43919 | I14: 2153.75 | J14: =I14/I13-1 -> 0.010405476 | L14: =L13+1 -> 6 | M14: =M13+365 -> 43919 | N14: 14.325736 | O14: =N14/N13-1 -> -0.26025887
B15: =B14+1 -> 7 | C15: =C14+365 -> 44284 | D15: 11028.62 | E15: =D15/D14-1 -> 0.11278807 | G15: =G14+1 -> 7 | H15: =H14+365 -> 44284 | I15: 2399.26 | J15: =I15/I14-1 -> 0.11399187 | L15: =L14+1 -> 7 | M15: =M14+365 -> 44284 | N15: 16.608509 | O15: =N15/N14-1 -> 0.15934766
B16: =B15+1 -> 8 | C16: =C15+365 -> 44649 | D16: 12276.5 | E16: =D16/D15-1 -> 0.11314924 | G16: =G15+1 -> 8 | H16: =H15+365 -> 44649 | I16: 2409.18 | J16: =I16/I15-1 -> 0.0041346082 | L16: =L15+1 -> 8 | M16: =M15+365 -> 44649 | N16: 16.674359 | O16: =N16/N15-1 -> 0.0039648905
B17: =B16+1 -> 9 | C17: =C16+365 -> 45014 | D17: 13315.97 | E17: =D17/D16-1 -> 0.084671527 | G17: =G16+1 -> 9 | H17: =H16+365 -> 45014 | I17: 2443.2 | J17: =I17/I16-1 -> 0.014120987 | L17: =L16+1 -> 9 | M17: =M16+365 -> 45014 | N17: 15.52909 | O17: =N17/N16-1 -> -0.068684486
B18: =B17+1 -> 10 | C18: =C17+365 -> 45379 | D18: 14096.11 | E18: =D18/D17-1 -> 0.058586795 | G18: =G17+1 -> 10 | H18: =H17+365 -> 45379 | I18: 2957.32 | J18: =I18/I17-1 -> 0.21042895 | L18: =L17+1 -> 10 | M18: =M17+365 -> 45379 | N18: 16.11273 | O18: =N18/N17-1 -> 0.037583665
B19: =B18+1 -> 11 | C19: =C18+365 -> 45744 | D19: =FORECAST(B19,D9:D18,B9:B18) -> 14169.946 | E19: =D19/D18-1 -> 0.0052380408 | G19: =G18+1 -> 11 | H19: =H18+365 -> 45744 | I19: =FORECAST(G19,I9:I18,G9:G18) -> 2925.0113 | J19: =I19/I18-1 -> -0.010924982 | L19: =L18+1 -> 11 | M19: =M18+365 -> 45744 | N19: =FORECAST(L19,N9:N18,L9:L18) -> 18.592076 | O19: =N19/N18-1 -> 0.15387497
B20: =B19+1 -> 12 | C20: =C19+365 -> 46109 | D20: =FORECAST(B20,D10:D19,B10:B19) -> 14927.117 | E20: =D20/D19-1 -> 0.053435 | G20: =G19+1 -> 12 | H20: =H19+365 -> 46109 | I20: =FORECAST(G20,I10:I19,G10:G19) -> 3027.9545 | J20: =I20/I19-1 -> 0.03519412 | L20: =L19+1 -> 12 | M20: =M19+365 -> 46109 | N20: =FORECAST(L20,N10:N19,L10:L19) -> 18.825545 | O20: =N20/N19-1 -> 0.012557446
B21: =B20+1 -> 13 | C21: =C20+365 -> 46474 | D21: =FORECAST(B21,D11:D20,B11:B20) -> 15634.231 | E21: =D21/D20-1 -> 0.047371132 | G21: =G20+1 -> 13 | H21: =H20+365 -> 46474 | I21: =FORECAST(G21,I11:I20,G11:G20) -> 3143.2523 | J21: =I21/I20-1 -> 0.038077759 | L21: =L20+1 -> 13 | M21: =M20+365 -> 46474 | N21: =FORECAST(L21,N11:N20,L11:L20) -> 18.996099 | O21: =N21/N20-1 -> 0.0090597434
B22: =B21+1 -> 14 | C22: =C21+365 -> 46839 | D22: =FORECAST(B22,D12:D21,B12:B21) -> 16415.717 | E22: =D22/D21-1 -> 0.049985554 | G22: =G21+1 -> 14 | H22: =H21+365 -> 46839 | I22: =FORECAST(G22,I12:I21,G12:G21) -> 3279.7854 | J22: =I22/I21-1 -> 0.043436914 | L22: =L21+1 -> 14 | M22: =M21+365 -> 46839 | N22: =FORECAST(L22,N12:N21,L12:L21) -> 19.055417 | O22: =N22/N21-1 -> 0.0031226438
B23: =B22+1 -> 15 | C23: =C22+365 -> 47204 | D23: =FORECAST(B23,D13:D22,B13:B22) -> 17239.914 | E23: =D23/D22-1 -> 0.050207812 | G23: =G22+1 -> 15 | H23: =H22+365 -> 47204 | I23: =FORECAST(G23,I13:I22,G13:G22) -> 3435.8797 | J23: =I23/I22-1 -> 0.047592839 | L23: =L22+1 -> 15 | M23: =M22+365 -> 47204 | N23: =FORECAST(L23,N13:N22,L13:L22) -> 18.985889 | O23: =N23/N22-1 -> -0.0036487199
B24: =B23+1 -> 16 | C24: =C23+365 -> 47569 | D24: =FORECAST(B24,D14:D23,B14:B23) -> 18080.414 | E24: =D24/D23-1 -> 0.048753123 | G24: =G23+1 -> 16 | H24: =H23+365 -> 47569 | I24: =FORECAST(G24,I14:I23,G14:G23) -> 3587.2981 | J24: =I24/I23-1 -> 0.044069739 | L24: =L23+1 -> 16 | M24: =M23+365 -> 47569 | N24: =FORECAST(L24,N14:N23,L14:L23) -> 20.138783 | O24: =N24/N23-1 -> 0.060723724

Sheet Beta Regression
B2: ='Data Sheet'!B1 -> GODREJ CONSUMER PRODUCTS LTD
B3: (GODREJCP | BSE Code: 532424)
B5: Beta Regression - GODREJ CONSUMER PRODUCTS LTD
B7: Regression Beta - 1 Year Weekly
B9: Godrej Consumer Products Weekly Returns | F9: NIFTY Returns | I9: Beta Drifting
B11: Date | C11: Closing Price | D11: Return | F11: Closing Price | G11: Return | I11: Levered Raw Beta | J11: =O11 -> 0.740835 | N11: beta 1 | O11: =SLOPE(D12:D65,G12:G65) -> 0.740835
B12: 45208 | C12: 967.26 | F12: 19751.05 | I12: Raw Beta Weight | J12: 0.75
B13: 45215 | C13: 972.38 | D13: =C13/C12-1 -> 0.0052933027 | F13: 19542.65 | G13: =F13/F12-1 -> -0.010551338 | N13: beta 2 | O13: =(_xlfn.COVARIANCE.S(D12:D65,G12:G65))/_xlfn.VAR.S(G12:G65) -> 0.740835
B14: 45222 | C14: 971.49 | D14: =C14/C13-1 -> -0.00091528003 | F14: 19047.25 | G14: =F14/F13-1 -> -0.025349684 | I14: Market Beta | J14: 1
B15: 45229 | C15: 1004.41 | D15: =C15/C14-1 -> 0.033886092 | F15: 19230.6 | G15: =F15/F14-1 -> 0.0096260615 | I15: Market Beta Weight | J15: 0.25 | N15: beta 3 | O15: =O37 -> 0.740835
B16: 45236 | C16: 968.59 | D16: =C16/C15-1 -> -0.035662727 | F16: 19425.35 | G16: =F16/F15-1 -> 0.010127089
B17: 45243 | C17: 985.89 | D17: =C17/C16-1 -> 0.017861014 | F17: 19731.8 | G17: =F17/F16-1 -> 0.015775778 | I17: Adjusted Beta | J17: =(J11*J12)+(J14*J15) -> 0.80562625
B18: 45250 | C18: 998.3 | D18: =C18/C17-1 -> 0.012587611 | F18: 19794.7 | G18: =F18/F17-1 -> 0.0031877477
B19: 45257 | C19: 1014.03 | D19: =C19/C18-1 -> 0.015756787 | F19: 20267.9 | G19: =F19/F18-1 -> 0.023905389
B20: 45264 | C20: 1010.22 | D20: =C20/C19-1 -> -0.0037572853 | F20: 20969.4 | G20: =F20/F19-1 -> 0.034611381 | N20: SUMMARY OUTPUT
B21: 45271 | C21: 1030.59 | D21: =C21/C20-1 -> 0.020163925 | F21: 21456.65 | G21: =F21/F20-1 -> 0.023236239
B22: 45278 | C22: 1062.33 | D22: =C22/C21-1 -> 0.030797892 | F22: 21349.4 | G22: =F22/F21-1 -> -0.0049984504 | N22: Regression Statistics
B23: 45285 | C23: 1118.65 | D23: =C23/C22-1 -> 0.053015541 | F23: 21731.4 | G23: =F23/F22-1 -> 0.017892775 | N23: Multiple R | O23: 0.34239135
B24: 45292 | C24: 1206.32 | D24: =C24/C23-1 -> 0.078371251 | F24: 21710.8 | G24: =F24/F23-1 -> -0.00094793709 | N24: R Square | O24: 0.11723184
B25: 45299 | C25: 1142.68 | D25: =C25/C24-1 -> -0.052755488 | F25: 21894.55 | G25: =F25/F24-1 -> 0.0084635297 | N25: Adjusted R Square | O25: 0.099922657
B26: 45306 | C26: 1136.5 | D26: =C26/C25-1 -> -0.0054083383 | F26: 21622.4 | G26: =F26/F25-1 -> -0.012430034 | N26: Standard Error | O26: 0.031829075
B27: 45313 | C27: 1144.46 | D27: =C27/C26-1 -> 0.0070039595 | F27: 21352.6 | G27: =F27/F26-1 -> -0.012477801 | N27: Observations | O27: 53
B28: 45320 | C28: 1223.13 | D28: =C28/C27-1 -> 0.068739842 | F28: 21853.8 | G28: =F28/F27-1 -> 0.023472551
B29: 45327 | C29: 1205.13 | D29: =C29/C28-1 -> -0.014716342 | F29: 21782.5 | G29: =F29/F28-1 -> -0.0032625905 | N29: ANOVA
B30: 45334 | C30: 1227.58 | D30: =C30/C29-1 -> 0.018628696 | F30: 22040.7 | G30: =F30/F29-1 -> 0.011853552 | O30: df | P30: SS | Q30: MS | R30: F | S30: Significance F
B31: 45341 | C31: 1237.07 | D31: =C31/C30-1 -> 0.0077306571 | F31: 22212.7 | G31: =F31/F30-1 -> 0.0078037449 | N31: Regression | O31: 1 | P31: 0.0068614691 | Q31: 0.0068614691 | R31: 6.7728129 | S31: 0.012087864
B32: 45348 | C32: 1253.39 | D32: =C32/C31-1 -> 0.013192463 | F32: 22338.75 | G32: =F32/F31-1 -> 0.0056746816 | N32: Residual | O32: 51 | P32: 0.05166759 | Q32: 0.00101309
B33: 45355 | C33: 1220.56 | D33: =C33/C32-1 -> -0.026192965 | F33: 22493.55 | G33: =F33/F32-1 -> 0.0069296626 | N33: Total | O33: 52 | P33: 0.058529059
B34: 45362 | C34: 1199.25 | D34: =C34/C33-1 -> -0.017459199 | F34: 22023.35 | G34: =F34/F33-1 -> -0.02090377
B35: 45369 | C35: 1208.1 | D35: =C35/C34-1 -> 0.0073796123 | F35: 22096.75 | G35: =F35/F34-1 -> 0.0033328263 | O35: Coefficients | P35: Standard Error | Q35: t Stat | R35: P-value | S35: Lower 95% | T35: Upper 95% | U35: Lower 95.0% | V35: Upper 95.0%
B36: 45376 | C36: 1237.92 | D36: =C36/C35-1 -> 0.024683387 | F36: 22326.9 | G36: =F36/F35-1 -> 0.010415559 | N36: Intercept | O36: 0.0033462633 | P36: 0.0045529703 | Q36: 0.73496268 | R36: 0.46572853 | S36: -0.0057942061 | T36: 0.012486733 | U36: -0.0057942061 | V36: 0.012486733
B37: 45383 | C37: 1196.68 | D37: =C37/C36-1 -> -0.033313946 | F37: 22513.7 | G37: =F37/F36-1 -> 0.0083665892 | N37: X Variable 1 | O37: 0.740835 | P37: 0.28466689 | Q37: 2.6024629 | R37: 0.012087864 | S37: 0.16934238 | T37: 1.3123276 | U37: 0.16934238 | V37: 1.3123276
B38: 45390 | C38: 1186.44 | D38: =C38/C37-1 -> -0.0085570077 | F38: 22519.4 | G38: =F38/F37-1 -> 0.00025317918
B39: 45397 | C39: 1155.89 | D39: =C39/C38-1 -> -0.0257493 | F39: 22147 | G39: =F39/F38-1 -> -0.016536853
B40: 45404 | C40: 1189.16 | D40: =C40/C39-1 -> 0.028783016 | F40: 22419.95 | G40: =F40/F39-1 -> 0.012324468
B41: 45411 | C41: 1237.32 | D41: =C41/C40-1 -> 0.040499176 | F41: 22475.85 | G41: =F41/F40-1 -> 0.0024933151
B42: 45418 | C42: 1306.3 | D42: =C42/C41-1 -> 0.055749523 | F42: 22055.2 | G42: =F42/F41-1 -> -0.018715644
B43: 45425 | C43: 1284.99 | D43: =C43/C42-1 -> -0.016313251 | F43: 22466.1 | G43: =F43/F42-1 -> 0.018630527
B44: 45432 | C44: 1305.57 | D44: =C44/C43-1 -> 0.016015689 | F44: 22957.1 | G44: =F44/F43-1 -> 0.021855151
B45: 45439 | C45: 1265.72 | D45: =C45/C44-1 -> -0.030523067 | F45: 22530.7 | G45: =F45/F44-1 -> -0.018573775
...

Sheet WACC
B2: ='Data Sheet'!B1 -> GODREJ CONSUMER PRODUCTS LTD
B3: (GODREJCP | BSE Code: 532424)
B5: Weighted Average Cost of Capital- GODREJ CONSUMER PRODUCTS LTD
B7: All figures are in INR unless stated otherwise.
B9: Peer Comps
G10: Debt/ | H10: Debt/ | I10: Levered | J10: Unlevered
B11: Name | C11: Country | D11: Total Debt | E11: Total Equity | F11: Tax Rate 1 | G11: Equity | H11: Capital | I11: Beta 2 | J11: Beta 3
B13: Godrej Consumer | C13: India | D13: 3222.2 | E13: 136678 | F13: 0.3 | G13: =D13/E13 -> 0.023575118 | H13: =D13/(D13+E13) -> 0.023032133 | I13: 0.74 | J13: =I13/(1+(1-F13)*G13) -> 0.72798635
B14: Dabur India | C14: India | D14: 1365.09 | E14: 101269.87 | F14: 0.3 | G14: =D14/E14 -> 0.013479725 | H14: =D14/(D14+E14) -> 0.013300439 | I14: 0.69029221 | J14: =I14/(1+(1-F14)*G14) -> 0.68383963
B15: Emami | C15: India | D15: 93.95 | E15: 30592.1 | F15: 0.3 | G15: =D15/E15 -> 0.0030710543 | H15: =D15/(D15+E15) -> 0.0030616518 | I15: 0.41363446 | J15: =I15/(1+(1-F15)*G15) -> 0.41274716
B16: Jyothy Labs | C16: India | D16: 50.56 | E16: 18804.75 | F16: 0.3 | G16: =D16/E16 -> 0.0026886824 | H16: =D16/(D16+E16) -> 0.0026814728 | I16: 0.58255317 | J16: =I16/(1+(1-F16)*G16) -> 0.58145881
B17: Bajaj Consumer | C17: India | D17: 8.75 | E17: 3269.69 | F17: 0.3 | G17: =D17/E17 -> 0.0026760947 | H17: =D17/(D17+E17) -> 0.0026689523 | I17: 0.47654062 | J17: =I17/(1+(1-F17)*G17) -> 0.4756496
E19: Average | F19: =AVERAGE(F14:F17) -> 0.3 | G19: =AVERAGE(G14:G17) -> 0.0054788891 | H19: =AVERAGE(H14:H17) -> 0.0054281289 | I19: =AVERAGE(I14:I17) -> 0.54075511 | J19: =AVERAGE(J14:J17) -> 0.5384238
E20: Median | F20: =MEDIAN(F14:F17) -> 0.3 | G20: =MEDIAN(G14:G17) -> 0.0028798683 | H20: =MEDIAN(H14:H17) -> 0.0028715623 | I20: =MEDIAN(I14:I17) -> 0.52954689 | J20: =MEDIAN(J14:J17) -> 0.52855421
B23: Cost of Debt | G23: Cost of Equity
B25: Pre-tax Cost of Debt | E25: =310/3222.2 -> 0.09620756 | G25: Risk Free Rate | J25: 0.06946
B26: Tax Rate | E26: =F20 -> 0.3 | G26: Equity Risk Premium | J26: =(0.1677-J25) -> 0.09824
B27: After Tax Cost of Debt | E27: =E25*(1-E26) -> 0.067345292 | G27: Levered Beta 4 | J27: =J36 -> 0.68625505
G28: Cost of Equity | J28: =J25+(J26*J27) -> 0.1368777
B31: Capital Structure | G31: Levered Beta
D33: Current | E33: Target | G33: Comps Median Unlevered Beta | J33: =J20 -> 0.52855421
B34: Total Debt | C34: =D13 -> 3222.2 | D34: =C34/$C$36 -> 0.023032133 | E34: =H19 -> 0.0054281289 | G34: Target Debt/ Equity | J34: =E38 -> 0.0054577543
B35: Market Capitalization | C35: =E13 -> 136678 | D35: =C35/$C$36 -> 0.97696787 | E35: =E36-E34 -> 0.99457187 | G35: Tax Rate | J35: =E26 -> 0.3
B36: Total Capitalization | C36: =SUM(C34:C35) -> 139900.2 | D36: 1 | E36: 1 | G36: Levered Beta | J36: =J33*(1+(1-J34)*J35) -> 0.68625505
B38: Debt / Equity | D38: =D34/D35 -> 0.023575118 | E38: =E34/E35 -> 0.0054577543 | G38: Weighted Average Cost of Capital
B40: 1. Tax Rate considered as Marginal Tax Rate for the country | G40: Cost of Equity | J40: =J28 -> 0.1368777
B41: 2. Levered Beta is based on 5 year monthly data | G41: Equity Weight | J41: =E35 -> 0.99457187
B42: 3. Unlevered Beta = Levered Beta/(1+(1-Tax Rate) x Debt/Equity)
B43: 3. Levered Beta = Unlevered Beta/(1+(1-Tax Rate) x Debt/Equity) | G43: Cost of Debt | J43: =E27 -> 0.067345292
G44: Debt Weight | J44: =E34 -> 0.0054281289
G46: WACC | J46: =(J40*J41)+(J43*J44) -> 0.13650027

Sheet Intrinsic Growth
B2: ='Data Sheet'!B1 -> GODREJ CONSUMER PRODUCTS LTD
B3: (GODREJCP | BSE Code: 532424)
B5: Intrinsic Growth - GODREJ CONSUMER PRODUCTS LTD
B7: Calculation of ROIC | G7: ='Raw FS'!J$1 -> 43891 | H7: ='Raw FS'!K$1 -> 44256 | I7: ='Raw FS'!L$1 -> 44621 | J7: ='Raw FS'!M$1 -> 44986 | K7: ='Raw FS'!N$1 -> 45352
B9: Current Assets
B10: ='Raw FS'!B35 -> Inventories | G10: ='Raw FS'!J35 -> 1703 | H10: ='Raw FS'!K35 -> 1716 | I10: ='Raw FS'!L35 -> 2130 | J10: ='Raw FS'!M35 -> 1537 | K10: ='Raw FS'!N35 -> 1271
B11: ='Raw FS'!B36 -> Trade receivables | G11: ='Raw FS'!J36 -> 1157 | H11: ='Raw FS'!K36 -> 1004 | I11: ='Raw FS'!L36 -> 1116 | J11: ='Raw FS'!M36 -> 1245 | K11: ='Raw FS'!N36 -> 1535
B12: ='Raw FS'!B39 -> Other asset items | G12: ='Raw FS'!J39 -> 1289 | H12: ='Raw FS'!K39 -> 1209 | I12: ='Raw FS'!L39 -> 1377 | J12: ='Raw FS'!M39 -> 1256 | K12: ='Raw FS'!N39 -> 1012
B13: Total Current Assets | G13: =SUM(G10:G12) -> 4149 | H13: =SUM(H10:H12) -> 3929 | I13: =SUM(I10:I12) -> 4623 | J13: =SUM(J10:J12) -> 4038 | K13: =SUM(K10:K12) -> 3818
B15: Current Liabilities
B16: ='Raw FS'!B11 -> Trade Payables | G16: ='Raw FS'!J11 -> 2480 | H16: ='Raw FS'!K11 -> 2012 | I16: ='Raw FS'!L11 -> 2163 | J16: ='Raw FS'!M11 -> 1823 | K16: ='Raw FS'!N11 -> 1675
B17: ='Raw FS'!B12 -> Advance from Customers | G17: ='Raw FS'!J12 -> 25 | H17: ='Raw FS'!K12 -> 27 | I17: ='Raw FS'!L12 -> 30 | J17: ='Raw FS'!M12 -> 38 | K17: ='Raw FS'!N12 -> 30
B18: ='Raw FS'!B13 -> Other liability items | G18: ='Raw FS'!J13 -> 901 | H18: ='Raw FS'!K13 -> 901 | I18: ='Raw FS'!L13 -> 629 | J18: ='Raw FS'!M13 -> 652 | K18: ='Raw FS'!N13 -> 865
B19: Total Current Liabilities | G19: =SUM(G16:G18) -> 3406 | H19: =SUM(H16:H18) -> 2940 | I19: =SUM(I16:I18) -> 2822 | J19: =SUM(J16:J18) -> 2513 | K19: =SUM(K16:K18) -> 2570
B21: Net Working Capital | G21: =G13-G19 -> 743 | H21: =H13-H19 -> 989 | I21: =I13-I19 -> 1801 | J21: =J13-J19 -> 1525 | K21: =K13-K19 -> 1248
B23: Non Current Assets
B24: ='Raw FS'!B17 -> Land | G24: ='Raw FS'!J17 -> 146 | H24: ='Raw FS'!K17 -> 144 | I24: ='Raw FS'!L17 -> 147 | J24: ='Raw FS'!M17 -> 145 | K24: ='Raw FS'!N17 -> 157
B25: ='Raw FS'!B18 -> Building | G25: ='Raw FS'!J18 -> 699 | H25: ='Raw FS'!K18 -> 757 | I25: ='Raw FS'!L18 -> 812 | J25: ='Raw FS'!M18 -> 854 | K25: ='Raw FS'!N18 -> 791
B26: ='Raw FS'!B19 -> Plant Machinery | G26: ='Raw FS'!J19 -> 713 | H26: ='Raw FS'!K19 -> 809 | I26: ='Raw FS'!L19 -> 942 | J26: ='Raw FS'!M19 -> 1178 | K26: ='Raw FS'!N19 -> 1186
B27: ='Raw FS'!B20 -> Ships Vessels | G27: ='Raw FS'!J20 -> 0 | H27: ='Raw FS'!K20 -> 1 | I27: ='Raw FS'!L20 -> 2 | J27: ='Raw FS'!M20 -> 12 | K27: ='Raw FS'!N20 -> 17
B28: ='Raw FS'!B21 -> Equipments | G28: ='Raw FS'!J21 -> 33 | H28: ='Raw FS'!K21 -> 36 | I28: ='Raw FS'!L21 -> 41 | J28: ='Raw FS'!M21 -> 51 | K28: ='Raw FS'!N21 -> 47
B29: ='Raw FS'!B22 -> Computers | G29: ='Raw FS'!J22 -> 59 | H29: ='Raw FS'!K22 -> 64 | I29: ='Raw FS'!L22 -> 75 | J29: ='Raw FS'!M22 -> 78 | K29: ='Raw FS'!N22 -> 67
B30: ='Raw FS'!B23 -> Furniture n fittings | G30: ='Raw FS'!J23 -> 35 | H30: ='Raw FS'!K23 -> 37 | I30: ='Raw FS'!L23 -> 36 | J30: ='Raw FS'!M23 -> 35 | K30: ='Raw FS'!N23 -> 30
B31: ='Raw FS'!B24 -> Vehicles | G31: ='Raw FS'!J24 -> 44 | H31: ='Raw FS'!K24 -> 60 | I31: ='Raw FS'!L24 -> 65 | J31: ='Raw FS'!M24 -> 63 | K31: ='Raw FS'!N24 -> 31
B32: ='Raw FS'!B25 -> Intangible Assets | G32: ='Raw FS'!J25 -> 8036 | H32: ='Raw FS'!K25 -> 7753 | I32: ='Raw FS'!L25 -> 8083 | J32: ='Raw FS'!M25 -> 8687 | K32: ='Raw FS'!N25 -> 10696
B33: ='Raw FS'!B26 -> Other fixed assets | G33: ='Raw FS'!J26 -> 126 | H33: ='Raw FS'!K26 -> 130 | I33: ='Raw FS'!L26 -> 144 | J33: ='Raw FS'!M26 -> 145 | K33: ='Raw FS'!N26 -> 151
B35: Gross Block | G35: =SUM(G24:G34) -> 9891 | H35: =SUM(H24:H34) -> 9791 | I35: =SUM(I24:I34) -> 10347 | J35: =SUM(J24:J34) -> 11248 | K35: =SUM(K24:K34) -> 13173
B36: Accumulated Depreciation | G36: =-'Raw FS'!J28 -> -661 | H36: =-'Raw FS'!K28 -> -886 | I36: =-'Raw FS'!L28 -> -1127 | J36: =-'Raw FS'!M28 -> -1315 | K36: =-'Raw FS'!N28 -> -2732
B37: Net Non Current Assets | G37: =SUM(G35:G36) -> 9230 | H37: =SUM(H35:H36) -> 8905 | I37: =SUM(I35:I36) -> 9220 | J37: =SUM(J35:J36) -> 9933 | K37: =SUM(K35:K36) -> 10441
B39: Invested Capital | G39: =G37+G21 -> 9973 | H39: =H37+H21 -> 9894 | I39: =I37+I21 -> 11021 | J39: =J37+J21 -> 11458 | K39: =K37+K21 -> 11689
B40: EBIT | G40: =HistoricalFS!H30+HistoricalFS!H24 -> 1956.47 | H40: =HistoricalFS!I30+HistoricalFS!I24 -> 2195.41 | I40: =HistoricalFS!J30+HistoricalFS!J24 -> 2199.25 | J40: =HistoricalFS!K30+HistoricalFS!K24 -> 2206.91 | K40: =HistoricalFS!L30+HistoricalFS!L24 -> 2716.36
B42: ROIC | G42: =G40/G39 -> 0.19617668 | H42: =H40/H39 -> 0.22189307 | I42: =I40/I39 -> 0.19955086 | J42: =J40/J39 -> 0.19260866 | K42: =K40/K39 -> 0.232386
B44: Calculation of Reinvestment Rate | G44: =G7 -> 43891 | H44: =H7 -> 44256 | I44: =I7 -> 44621 | J44: =J7 -> 44986 | K44: =K7 -> 45352
B46: Net Capex | G46: =SUM('Raw FS'!J56:J57) -> -152 | H46: =SUM('Raw FS'!K56:K57) -> -164 | I46: =SUM('Raw FS'!L56:L57) -> 3 | J46: =SUM('Raw FS'!M56:M57) -> 8 | K46: =SUM('Raw FS'!N56:N57) -> 31
B47: Change in Working Capital | H47: =H21-G21 -> 246 | I47: =I21-H21 -> 812 | J47: =J21-I21 -> -276 | K47: =K21-J21 -> -277
B49: EBIT | G49: =G40 -> 1956.47 | H49: =H40 -> 2195.41 | I49: =I40 -> 2199.25 | J49: =J40 -> 2206.91 | K49: =K40 -> 2716.36
