Workbook
Name IQ_CH: 110000
Name IQ_CQ: 5000
Name IQ_CY: 10000
Name IQ_DAILY: 500000
Name IQ_FH: 100000
Name IQ_FQ: 500
Name IQ_FY: 1000
Name IQ_LTM: 2000
Name IQ_MONTH: 15000
Name IQ_NTM: 6000
Name IQ_WEEK: 50000
Name IQ_YTD: 3000
Name UPDATE: 'Data Sheet'!$E$1

Sheet Financials>

Sheet HistoricalFS
B2: ='Data Sheet'!B1 -> GODREJ CONSUMER PRODUCTS LTD
B3: (GODREJCP | BSE Code: 532424)
B5: ="Historical Financial Statement - "&'Data Sheet'!B1 -> Historical Financial Statement - GODREJ CONSUMER PRODUCTS LTD
B6: Years | C6: ='Data Sheet'!B16 -> 42094 | D6: ='Data Sheet'!C16 -> 42460 | E6: ='Data Sheet'!D16 -> 42825 | F6: ='Data Sheet'!E16 -> 43190 | G6: ='Data Sheet'!F16 -> 43555 | H6: ='Data Sheet'!G16 -> 43921 | I6: ='Data Sheet'!H16 -> 44286 | J6: ='Data Sheet'!I16 -> 44651 | ... L6: ='Data Sheet'!K16 -> 45382
C7: 1 | D7: 2 | E7: 3 | F7: 4 | G7: 5 | H7: 6 | I7: 7 | J7: 8 | K7: 9 | L7: 10
A8: # | B8: Income Statement
B9: Sales | C9: =IFERROR('Data Sheet'!B17,0) -> 8273.15 | D9: =IFERROR('Data Sheet'!C17,0) -> 8423.88 | E9: =IFERROR('Data Sheet'!D17,0) -> 9267.91 | F9: =IFERROR('Data Sheet'!E17,0) -> 9847.43 | G9: =IFERROR('Data Sheet'!F17,0) -> 10314.34 | H9: =IFERROR('Data Sheet'!G17,0) -> 9910.8 | I9: =IFERROR('Data Sheet'!H17,0) -> 11028.62 | J9: =IFERROR('Data Sheet'!I17,0) -> 12276.5 | ... L9: =IFERROR('Data Sheet'!K17,0) -> 14096.11
B10: Sales Growth | C10: - | D10: =D9/C9-1 -> 0.018219179 | E10: =E9/D9-1 -> 0.10019492 | F10: =F9/E9-1 -> 0.06252974 | G10: =G9/F9-1 -> 0.047414402 | H10: =H9/G9-1 -> -0.039124171 | I10: =I9/H9-1 -> 0.11278807 | J10: =J9/I9-1 -> 0.11314924 | K10: =K9/J9-1 -> 0.084671527 | L10: =L9/K9-1 -> 0.058586795
B12: COGS | C12: =IFERROR(SUM('Data Sheet'!B18,'Data Sheet'!B20:B22)-1*'Data Sheet'!B19,0) -> 4952.36 | D12: =IFERROR(SUM('Data Sheet'!C18,'Data Sheet'!C20:C22)-1*'Data Sheet'!C19,0) -> 5157.59 | E12: =IFERROR(SUM('Data Sheet'!D18,'Data Sheet'!D20:D22)-1*'Data Sheet'!D19,0) -> 5512.85 | F12: =IFERROR(SUM('Data Sheet'!E18,'Data Sheet'!E20:E22)-1*'Data Sheet'!E19,0) -> 5751.63 | G12: =IFERROR(SUM('Data Sheet'!F18,'Data Sheet'!F20:F22)-1*'Data Sheet'!F19,0) -> 6071.83 | H12: =IFERROR(SUM('Data Sheet'!G18,'Data Sheet'!G20:G22)-1*'Data Sheet'!G19,0) -> 5777.48 | I12: =IFERROR(SUM('Data Sheet'!H18,'Data Sheet'!H20:H22)-1*'Data Sheet'!H19,0) -> 6556.24 | J12: =IFERROR(SUM('Data Sheet'!I18,'Data Sheet'!I20:I22)-1*'Data Sheet'!I19,0) -> 7743.02 | ... L12: =IFERROR(SUM('Data Sheet'!K18,'Data Sheet'!K20:K22)-1*'Data Sheet'!K19,0) -> 8140.92
B13: COGS % Sales | C13: =C12/C9 -> 0.59860633 | D13: =D12/D9 -> 0.61225825 | E13: =E12/E9 -> 0.59483206 | F13: =F12/F9 -> 0.58407422 | G13: =G12/G9 -> 0.58867848 | H13: =H12/H9 -> 0.5829479 | I13: =I12/I9 -> 0.5944751 | J13: =J12/J9 -> 0.63071885 | ... L13: =L12/L9 -> 0.57752955
B15: Gross Profit | C15: =C9-C12 -> 3320.79 | D15: =D9-D12 -> 3266.29 | E15: =E9-E12 -> 3755.06 | F15: =F9-F12 -> 4095.8 | G15: =G9-G12 -> 4242.51 | H15: =H9-H12 -> 4133.32 | I15: =I9-I12 -> 4472.38 | J15: =J9-J12 -> 4533.48 | ... L15: =L9-L12 -> 5955.19
B16: Gross Margins | C16: =C15/C9 -> 0.40139367 | D16: =D15/D9 -> 0.38774175 | E16: =E15/E9 -> 0.40516794 | F16: =F15/F9 -> 0.41592578 | G16: =G15/G9 -> 0.41132152 | H16: =H15/H9 -> 0.4170521 | I16: =I15/I9 -> 0.4055249 | J16: =J15/J9 -> 0.36928115 | ... L16: =L15/L9 -> 0.42247045
B18: Selling & General Expenses | C18: =IFERROR(SUM('Data Sheet'!B23:B24),0) -> 1941.84 | D18: =IFERROR(SUM('Data Sheet'!C23:C24),0) -> 1608.91 | E18: =IFERROR(SUM('Data Sheet'!D23:D24),0) -> 1848.35 | F18: =IFERROR(SUM('Data Sheet'!E23:E24),0) -> 2011.4 | G18: =IFERROR(SUM('Data Sheet'!F23:F24),0) -> 2110.94 | H18: =IFERROR(SUM('Data Sheet'!G23:G24),0) -> 1979.57 | I18: =IFERROR(SUM('Data Sheet'!H23:H24),0) -> 2073.12 | J18: =IFERROR(SUM('Data Sheet'!I23:I24),0) -> 2124.3 | ... L18: =IFERROR(SUM('Data Sheet'!K23:K24),0) -> 2997.87
B19: S&G Exp % Sales | C19: =C18/C9 -> 0.23471592 | D19: =D18/D9 -> 0.19099394 | E19: =E18/E9 -> 0.19943547 | F19: =F18/F9 -> 0.20425634 | G19: =G18/G9 -> 0.2046607 | H19: =H18/H9 -> 0.19973867 | I19: =I18/I9 -> 0.18797637 | J19: =J18/J9 -> 0.17303792 | ... L19: =L18/L9 -> 0.21267357
B21: EBITDA | C21: =C15-C18 -> 1378.95 | D21: =D15-D18 -> 1657.38 | E21: =E15-E18 -> 1906.71 | F21: =F15-F18 -> 2084.4 | G21: =G15-G18 -> 2131.57 | H21: =H15-H18 -> 2153.75 | I21: =I15-I18 -> 2399.26 | J21: =J15-J18 -> 2409.18 | ... L21: =L15-L18 -> 2957.32
B22: EBITDA Margins | C22: =C21/C9 -> 0.16667775 | D22: =D21/D9 -> 0.19674782 | E22: =E21/E9 -> 0.20573247 | F22: =F21/F9 -> 0.21166944 | G22: =G21/G9 -> 0.20666082 | H22: =H21/H9 -> 0.21731344 | I22: =I21/I9 -> 0.21754852 | J22: =J21/J9 -> 0.19624323 | ... L22: =L21/L9 -> 0.20979689
B24: Depreciation | C24: =IFERROR('Data Sheet'!B26,0) -> 90.78 | D24: =IFERROR('Data Sheet'!C26,0) -> 100.63 | E24: =IFERROR('Data Sheet'!D26,0) -> 141.57 | F24: =IFERROR('Data Sheet'!E26,0) -> 155.68 | G24: =IFERROR('Data Sheet'!F26,0) -> 169.98 | H24: =IFERROR('Data Sheet'!G26,0) -> 197.28 | I24: =IFERROR('Data Sheet'!H26,0) -> 203.85 | J24: =IFERROR('Data Sheet'!I26,0) -> 209.93 | ... L24: =IFERROR('Data Sheet'!K26,0) -> 240.96
B25: Depreciation%Sales | C25: =C24/C9 -> 0.010972846 | D25: =D24/D9 -> 0.011945802 | E25: =E24/E9 -> 0.015275289 | F25: =F24/F9 -> 0.015809201 | G25: =G24/G9 -> 0.016479969 | H25: =H24/H9 -> 0.019905558 | I25: =I24/I9 -> 0.018483727 | J25: =J24/J9 -> 0.017100151 | ... L25: =L24/L9 -> 0.017094078
B27: EBIT | C27: =C21-C24 -> 1288.17 | D27: =D21-D24 -> 1556.75 | E27: =E21-E24 -> 1765.14 | F27: =F21-F24 -> 1928.72 | G27: =G21-G24 -> 1961.59 | H27: =H21-H24 -> 1956.47 | I27: =I21-I24 -> 2195.41 | J27: =J21-J24 -> 2199.25 | ... L27: =L21-L24 -> 2716.36
B28: EBIT Margin | C28: =C27/C9 -> 0.1557049 | D28: =D27/D9 -> 0.18480202 | E28: =E27/E9 -> 0.19045718 | F28: =F27/F9 -> 0.19586024 | G28: =G27/G9 -> 0.19018086 | H28: =H27/H9 -> 0.19740788 | I28: =I27/I9 -> 0.1990648 | J28: =J27/J9 -> 0.17914308 | ... L28: =L27/L9 -> 0.19270281
B30: Interest | C30: =IFERROR('Data Sheet'!B27,0) -> 112.46 | D30: =IFERROR('Data Sheet'!C27,0) -> 128.04 | E30: =IFERROR('Data Sheet'!D27,0) -> 154.19 | F30: =IFERROR('Data Sheet'!E27,0) -> 173.12 | G30: =IFERROR('Data Sheet'!F27,0) -> 238.21 | H30: =IFERROR('Data Sheet'!G27,0) -> 228.13 | I30: =IFERROR('Data Sheet'!H27,0) -> 137.65 | J30: =IFERROR('Data Sheet'!I27,0) -> 122.26 | ... L30: =IFERROR('Data Sheet'!K27,0) -> 309.57
B31: Interest % Sales | C31: =C30/C9 -> 0.013593371 | D31: =D30/D9 -> 0.015199647 | E31: =E30/E9 -> 0.016636976 | F31: =F30/F9 -> 0.017580221 | G31: =G30/G9 -> 0.023095031 | H31: =H30/H9 -> 0.023018323 | I31: =I30/I9 -> 0.012481163 | J31: =J30/J9 -> 0.0099588645 | ... L31: =L30/L9 -> 0.021961378
B33: Earnings Before Tax | C33: =IFERROR(C21-SUM(C24,C30),0) -> 1175.71 | D33: =IFERROR(D21-SUM(D24,D30),0) -> 1428.71 | E33: =IFERROR(E21-SUM(E24,E30),0) -> 1610.95 | F33: =IFERROR(F21-SUM(F24,F30),0) -> 1755.6 | G33: =IFERROR(G21-SUM(G24,G30),0) -> 1723.38 | H33: =IFERROR(H21-SUM(H24,H30),0) -> 1728.34 | I33: =IFERROR(I21-SUM(I24,I30),0) -> 2057.76 | J33: =IFERROR(J21-SUM(J24,J30),0) -> 2076.99 | ... L33: =IFERROR(L21-SUM(L24,L30),0) -> 2406.79
B34: EBT % Sales | C34: =C33/C9 -> 0.14211153 | D34: =D33/D9 -> 0.16960237 | E34: =E33/E9 -> 0.1738202 | F34: =F33/F9 -> 0.17828002 | G34: =G33/G9 -> 0.16708582 | H34: =H33/H9 -> 0.17438955 | I34: =I33/I9 -> 0.18658363 | J34: =J33/J9 -> 0.16918421 | ... L34: =L33/L9 -> 0.17074143
B36: Tax | C36: =IFERROR('Data Sheet'!B29,0) -> 272.29 | D36: =IFERROR('Data Sheet'!C29,0) -> 336.05 | E36: =IFERROR('Data Sheet'!D29,0) -> 379.16 | F36: =IFERROR('Data Sheet'!E29,0) -> 404.7 | G36: =IFERROR('Data Sheet'!F29,0) -> -256.2 | H36: =IFERROR('Data Sheet'!G29,0) -> 263.82 | I36: =IFERROR('Data Sheet'!H29,0) -> 359.54 | J36: =IFERROR('Data Sheet'!I29,0) -> 371.87 | ... L36: =IFERROR('Data Sheet'!K29,0) -> 758.78
B37: Effective Tax Rate | C37: =C36/C33 -> 0.23159623 | D37: =D36/D33 -> 0.23521218 | E37: =E36/E33 -> 0.23536423 | F37: =F36/F33 -> 0.23051948 | G37: =G36/G33 -> -0.14866135 | H37: =H36/H33 -> 0.15264358 | I37: =I36/I33 -> 0.17472397 | J37: =J36/J33 -> 0.17904275 | ... L37: =L36/L33 -> 0.31526639
B39: Net Profit | C39: =IFERROR(C33-C36,0) -> 903.42 | D39: =IFERROR(D33-D36,0) -> 1092.66 | E39: =IFERROR(E33-E36,0) -> 1231.79 | F39: =IFERROR(F33-F36,0) -> 1350.9 | G39: =IFERROR(G33-G36,0) -> 1979.58 | H39: =IFERROR(H33-H36,0) -> 1464.52 | I39: =IFERROR(I33-I36,0) -> 1698.22 | J39: =IFERROR(J33-J36,0) -> 1705.12 | ... L39: =IFERROR(L33-L36,0) -> 1648.01
B40: Net Margins | C40: =C39/C9 -> 0.10919904 | D40: =D39/D9 -> 0.12970982 | E40: =E39/E9 -> 0.13290915 | F40: =F39/F9 -> 0.137183 | G40: =G39/G9 -> 0.19192503 | H40: =H39/H9 -> 0.14777011 | I40: =I39/I9 -> 0.153983 | J40: =J39/J9 -> 0.13889301 | ... L40: =L39/L9 -> 0.1169124
B42: No of Equity Shares | C42: =IFERROR('Data Sheet'!B93,0) -> 102.14 | D42: =IFERROR('Data Sheet'!C93,0) -> 102.16 | E42: =IFERROR('Data Sheet'!D93,0) -> 102.18 | F42: =IFERROR('Data Sheet'!E93,0) -> 102.2 | G42: =IFERROR('Data Sheet'!F93,0) -> 102.22 | H42: =IFERROR('Data Sheet'!G93,0) -> 102.23 | I42: =IFERROR('Data Sheet'!H93,0) -> 102.25 | J42: =IFERROR('Data Sheet'!I93,0) -> 102.26 | ... L42: =IFERROR('Data Sheet'!K93,0) -> 102.28
B44: Earnings per Share | C44: =IFERROR(C39/C42,0) -> 8.8449187 | D44: =IFERROR(D39/D42,0) -> 10.695576 | E44: =IFERROR(E39/E42,0) -> 12.055099 | F44: =IFERROR(F39/F42,0) -> 13.2182 | G44: =IFERROR(G39/G42,0) -> 19.365878 | H44: =IFERROR(H39/H42,0) -> 14.325736 | I44: =IFERROR(I39/I42,0) -> 16.608509 | J44: =IFERROR(J39/J42,0) -> 16.674359 | ... L44: =IFERROR(L39/L42,0) -> 16.11273
B45: EPS Growth % | D45: =IFERROR(D44/C44-1,0) -> 0.2092339 | E45: =IFERROR(E44/D44-1,0) -> 0.12711081 | F45: =IFERROR(F44/E44-1,0) -> 0.096482059 | G45: =IFERROR(G44/F44-1,0) -> 0.46509193 | H45: =IFERROR(H44/G44-1,0) -> -0.26025887 | I45: =IFERROR(I44/H44-1,0) -> 0.15934766 | J45: =IFERROR(J44/I44-1,0) -> 0.0039648905 | K45: =IFERROR(K44/J44-1,0) -> -0.068684486 | L45: =IFERROR(L44/K44-1,0) -> 0.037583665
B47: Dividend per Share | C47: =IFERROR('Data Sheet'!B31/HistoricalFS!C42,0) -> 1.8329743 | D47: =IFERROR('Data Sheet'!C31/HistoricalFS!D42,0) -> 1.9165035 | E47: =IFERROR('Data Sheet'!D31/HistoricalFS!E42,0) -> 5 | F47: =IFERROR('Data Sheet'!E31/HistoricalFS!F42,0) -> 6.6663405 | G47: =IFERROR('Data Sheet'!F31/HistoricalFS!G42,0) -> 10 | H47: =IFERROR('Data Sheet'!G31/HistoricalFS!H42,0) -> 8 | I47: =IFERROR('Data Sheet'!H31/HistoricalFS!I42,0) -> 0 | J47: =IFERROR('Data Sheet'!I31/HistoricalFS!J42,0) -> 0 | ... L47: =IFERROR('Data Sheet'!K31/HistoricalFS!L42,0) -> 0
B48: Dividend payout ratio | C48: =IFERROR(C47/C44,0) -> 0.20723473 | D48: =IFERROR(D47/D44,0) -> 0.17918657 | E48: =IFERROR(E47/E44,0) -> 0.41476226 | F48: =IFERROR(F47/F44,0) -> 0.50433045 | G48: =IFERROR(G47/G44,0) -> 0.51637216 | H48: =IFERROR(H47/H44,0) -> 0.55843553 | I48: =IFERROR(I47/I44,0) -> 0 | J48: =IFERROR(J47/J44,0) -> 0 | ... L48: =IFERROR(L47/L44,0) -> 0
B50: Retained Earnings | C50: =IFERROR(IF(C44>C47,1-C48,0),0) -> 0.79276527 | D50: =IFERROR(IF(D44>D47,1-D48,0),0) -> 0.82081343 | E50: =IFERROR(IF(E44>E47,1-E48,0),0) -> 0.58523774 | F50: =IFERROR(IF(F44>F47,1-F48,0),0) -> 0.49566955 | G50: =IFERROR(IF(G44>G47,1-G48,0),0) -> 0.48362784 | H50: =IFERROR(IF(H44>H47,1-H48,0),0) -> 0.44156447 | I50: =IFERROR(IF(I44>I47,1-I48,0),0) -> 1 | J50: =IFERROR(IF(J44>J47,1-J48,0),0) -> 1 | ... L50: =IFERROR(IF(L44>L47,1-L48,0),0) -> 1
A52: # | B52: Balance Sheet
B54: Equity Share Capital | C54: =IFERROR('Data Sheet'!B57,0) -> 34.04 | D54: =IFERROR('Data Sheet'!C57,0) -> 34.05 | E54: =IFERROR('Data Sheet'!D57,0) -> 34.06 | F54: =IFERROR('Data Sheet'!E57,0) -> 68.13 | G54: =IFERROR('Data Sheet'!F57,0) -> 102.22 | H54: =IFERROR('Data Sheet'!G57,0) -> 102.23 | I54: =IFERROR('Data Sheet'!H57,0) -> 102.25 | J54: =IFERROR('Data Sheet'!I57,0) -> 102.26 | ... L54: =IFERROR('Data Sheet'!K57,0) -> 102.28
B55: Reserves | C55: =IFERROR('Data Sheet'!B58,0) -> 4276.65 | D55: =IFERROR('Data Sheet'!C58,0) -> 4232.91 | E55: =IFERROR('Data Sheet'!D58,0) -> 5267.89 | F55: =IFERROR('Data Sheet'!E58,0) -> 6190.18 | G55: =IFERROR('Data Sheet'!F58,0) -> 7164.7 | H55: =IFERROR('Data Sheet'!G58,0) -> 7796.13 | I55: =IFERROR('Data Sheet'!H58,0) -> 9336.65 | J55: =IFERROR('Data Sheet'!I58,0) -> 11453.67 | ... L55: =IFERROR('Data Sheet'!K58,0) -> 12496.29
B56: Borrowings | C56: =IFERROR('Data Sheet'!B59,0) -> 2717.15 | D56: =IFERROR('Data Sheet'!C59,0) -> 2891.12 | E56: =IFERROR('Data Sheet'!D59,0) -> 4000.93 | F56: =IFERROR('Data Sheet'!E59,0) -> 3507.57 | G56: =IFERROR('Data Sheet'!F59,0) -> 3382.05 | H56: =IFERROR('Data Sheet'!G59,0) -> 3574.97 | I56: =IFERROR('Data Sheet'!H59,0) -> 1863.97 | J56: =IFERROR('Data Sheet'!I59,0) -> 1704.34 | ... L56: =IFERROR('Data Sheet'!K59,0) -> 3222.2
B57: Other Liabilities | C57: =IFERROR('Data Sheet'!B60,0) -> 2097.18 | D57: =IFERROR('Data Sheet'!C60,0) -> 2520.66 | E57: =IFERROR('Data Sheet'!D60,0) -> 3637.37 | F57: =IFERROR('Data Sheet'!E60,0) -> 4097.89 | G57: =IFERROR('Data Sheet'!F60,0) -> 3444.58 | H57: =IFERROR('Data Sheet'!G60,0) -> 3406.95 | I57: =IFERROR('Data Sheet'!H60,0) -> 2940.92 | J57: =IFERROR('Data Sheet'!I60,0) -> 2821.85 | ... L57: =IFERROR('Data Sheet'!K60,0) -> 2571.31
B58: Total Liabilities | C58: =IFERROR('Data Sheet'!B61,0) -> 9125.02 | D58: =IFERROR('Data Sheet'!C61,0) -> 9678.74 | E58: =IFERROR('Data Sheet'!D61,0) -> 12940.25 | F58: =IFERROR('Data Sheet'!E61,0) -> 13863.77 | G58: =IFERROR('Data Sheet'!F61,0) -> 14093.55 | H58: =IFERROR('Data Sheet'!G61,0) -> 14880.28 | I58: =IFERROR('Data Sheet'!H61,0) -> 14243.79 | J58: =IFERROR('Data Sheet'!I61,0) -> 16082.12 | ... L58: =IFERROR('Data Sheet'!K61,0) -> 18392.08
...

Sheet Ratio Analysis
B2: ='Data Sheet'!B1 -> GODREJ CONSUMER PRODUCTS LTD
B3: (GODREJCP | BSE Code: 532424)
B5: ="Ratio Analysis of - "&'[1]Data Sheet'!B1 -> Ratio Analysis of - GODREJ CONSUMER PRODUCTS LTD
B6: Years | C6: ='[1]Data Sheet'!B16 -> 42094 | D6: ='[1]Data Sheet'!C16 -> 42460 | E6: ='[1]Data Sheet'!D16 -> 42825 | F6: ='[1]Data Sheet'!E16 -> 43190 | G6: ='[1]Data Sheet'!F16 -> 43555 | H6: ='[1]Data Sheet'!G16 -> 43921 | I6: ='[1]Data Sheet'!H16 -> 44286 | J6: ='[1]Data Sheet'!I16 -> 44651 | ... L6: ='[1]Data Sheet'!K16 -> 45382 | M6: Trend | N6: Mean | O6: Median
B8: Liquidity Ratio
B9: Current Ratio | C9: =HistoricalFS!C69/SUM('Raw FS'!E11:E13) -> 1.4317881 | D9: =HistoricalFS!D69/SUM('Raw FS'!F11:F13) -> 1.2659419 | E9: =HistoricalFS!E69/SUM('Raw FS'!G11:G13) -> 0.92216112 | F9: =HistoricalFS!F69/SUM('Raw FS'!H11:H13) -> 0.92323816 | G9: =HistoricalFS!G69/SUM('Raw FS'!I11:I13) -> 1.087434 | H9: =HistoricalFS!H69/SUM('Raw FS'!J11:J13) -> 1.0659219 | I9: =HistoricalFS!I69/SUM('Raw FS'!K11:K13) -> 1.154068 | J9: =HistoricalFS!J69/SUM('Raw FS'!L11:L13) -> 1.5428561 | ... L9: =HistoricalFS!L69/SUM('Raw FS'!N11:N13) -> 1.3047588 | N9: =IFERROR(AVERAGE(C9:L9),0) -> 1.1960862 | O9: =IFERROR(MEDIAN(C9:L9),0) -> 1.208381
B10: Quick Ratio | C10: =(HistoricalFS!C69-HistoricalFS!C67)/SUM('Raw FS'!E11:E13) -> 0.87793282 | D10: =(HistoricalFS!D69-HistoricalFS!D67)/SUM('Raw FS'!F11:F13) -> 0.74544006 | E10: =(HistoricalFS!E69-HistoricalFS!E67)/SUM('Raw FS'!G11:G13) -> 0.53379159 | F10: =(HistoricalFS!F69-HistoricalFS!F67)/SUM('Raw FS'!H11:H13) -> 0.53824061 | G10: =(HistoricalFS!G69-HistoricalFS!G67)/SUM('Raw FS'!I11:I13) -> 0.63501306 | H10: =(HistoricalFS!H69-HistoricalFS!H67)/SUM('Raw FS'!J11:J13) -> 0.56588667 | I10: =(HistoricalFS!I69-HistoricalFS!I67)/SUM('Raw FS'!K11:K13) -> 0.57030952 | J10: =(HistoricalFS!J69-HistoricalFS!J67)/SUM('Raw FS'!L11:L13) -> 0.78812544 | ... L10: =(HistoricalFS!L69-HistoricalFS!L67)/SUM('Raw FS'!N11:N13) -> 0.81023735 | N10: =IFERROR(AVERAGE(C10:L10),0) -> 0.67159918 | O10: =IFERROR(MEDIAN(C10:L10),0) -> 0.64301389
B11: Cash Ratio | C11: =HistoricalFS!C68/SUM('Raw FS'!E11:E13) -> 0.4621292 | D11: =HistoricalFS!D68/SUM('Raw FS'!F11:F13) -> 0.30019514 | E11: =HistoricalFS!E68/SUM('Raw FS'!G11:G13) -> 0.25093759 | F11: =HistoricalFS!F68/SUM('Raw FS'!H11:H13) -> 0.23431186 | G11: =HistoricalFS!G68/SUM('Raw FS'!I11:I13) -> 0.25971553 | H11: =HistoricalFS!H68/SUM('Raw FS'!J11:J13) -> 0.22611861 | I11: =HistoricalFS!I68/SUM('Raw FS'!K11:K13) -> 0.22864286 | J11: =HistoricalFS!J68/SUM('Raw FS'!L11:L13) -> 0.39254784 | ... L11: =HistoricalFS!L68/SUM('Raw FS'!N11:N13) -> 0.21281712 | N11: =IFERROR(AVERAGE(C11:L11),0) -> 0.27228953 | O11: =IFERROR(MEDIAN(C11:L11),0) -> 0.24262472
B13: Solvency Ratio
B14: Debt To Equity | C14: =HistoricalFS!C56/SUM(HistoricalFS!C54:C55) -> 0.63032832 | D14: =HistoricalFS!D56/SUM(HistoricalFS!D54:D55) -> 0.67755967 | E14: =HistoricalFS!E56/SUM(HistoricalFS!E54:E55) -> 0.75461481 | F14: =HistoricalFS!F56/SUM(HistoricalFS!F54:F55) -> 0.560466 | G14: =HistoricalFS!G56/SUM(HistoricalFS!G54:G55) -> 0.4654035 | H14: =HistoricalFS!H56/SUM(HistoricalFS!H54:H55) -> 0.45262181 | I14: =HistoricalFS!I56/SUM(HistoricalFS!I54:I55) -> 0.19747746 | J14: =HistoricalFS!J56/SUM(HistoricalFS!J54:J55) -> 0.14748618 | ... L14: =HistoricalFS!L56/SUM(HistoricalFS!L54:L55) -> 0.25575919 | N14: =IFERROR(AVERAGE(C14:L14),0) -> 0.42236048 | O14: =IFERROR(MEDIAN(C14:L14),0) -> 0.45901265
B15: Debt To Asset | C15: =HistoricalFS!C56/HistoricalFS!C71 -> 0.29776921 | D15: =HistoricalFS!D56/HistoricalFS!D71 -> 0.2987083 | E15: =HistoricalFS!E56/HistoricalFS!E71 -> 0.30918491 | F15: =HistoricalFS!F56/HistoricalFS!F71 -> 0.25300261 | G15: =HistoricalFS!G56/HistoricalFS!G71 -> 0.23997148 | H15: =HistoricalFS!H56/HistoricalFS!H71 -> 0.24024884 | I15: =HistoricalFS!I56/HistoricalFS!I71 -> 0.13086194 | J15: =HistoricalFS!J56/HistoricalFS!J71 -> 0.10597732 | ... L15: =HistoricalFS!L56/HistoricalFS!L71 -> 0.17519498 | N15: =IFERROR(AVERAGE(C15:L15),0) -> 0.21156993 | O15: =IFERROR(MEDIAN(C15:L15),0) -> 0.24011016
B16: Debt to Capital | C16: =HistoricalFS!C56/SUM(HistoricalFS!C54:C56) -> 0.38662662 | D16: =HistoricalFS!D56/SUM(HistoricalFS!D54:D56) -> 0.40389602 | E16: =HistoricalFS!E56/SUM(HistoricalFS!E54:E56) -> 0.43007434 | F16: =HistoricalFS!F56/SUM(HistoricalFS!F54:F56) -> 0.35916579 | G16: =HistoricalFS!G56/SUM(HistoricalFS!G54:G56) -> 0.3175941 | H16: =HistoricalFS!H56/SUM(HistoricalFS!H54:H56) -> 0.31158957 | I16: =HistoricalFS!I56/SUM(HistoricalFS!I54:I56) -> 0.16491121 | J16: =HistoricalFS!J56/SUM(HistoricalFS!J54:J56) -> 0.12852981 | ... L16: =HistoricalFS!L56/SUM(HistoricalFS!L54:L56) -> 0.20366897 | N16: =IFERROR(AVERAGE(C16:L16),0) -> 0.27817462 | O16: =IFERROR(MEDIAN(C16:L16),0) -> 0.31459183
B18: Activity Ratio
B19: Inventory Turnover | C19: =IFERROR(HistoricalFS!C9/HistoricalFS!C67,0) -> 7.719579 | D19: =IFERROR(HistoricalFS!D9/HistoricalFS!D67,0) -> 6.4453014 | E19: =IFERROR(HistoricalFS!E9/HistoricalFS!E67,0) -> 6.5613522 | F19: =IFERROR(HistoricalFS!F9/HistoricalFS!F67,0) -> 6.2415574 | G19: =IFERROR(HistoricalFS!G9/HistoricalFS!G67,0) -> 6.6177378 | H19: =IFERROR(HistoricalFS!H9/HistoricalFS!H67,0) -> 5.8192024 | I19: =IFERROR(HistoricalFS!I9/HistoricalFS!I67,0) -> 6.4259985 | J19: =IFERROR(HistoricalFS!J9/HistoricalFS!J67,0) -> 5.7640209 | ... L19: =IFERROR(HistoricalFS!L9/HistoricalFS!L67,0) -> 11.091265 | N19: =IFERROR(AVERAGE(C19:L19),0) -> 7.134878 | O19: =IFERROR(MEDIAN(C19:L19),0) -> 6.5033268
B20: Fixed Asset Turnover | C20: =IFERROR(HistoricalFS!C9/HistoricalFS!C60,0) -> 1.4904025 | D20: =IFERROR(HistoricalFS!D9/HistoricalFS!D60,0) -> 1.4202154 | E20: =IFERROR(HistoricalFS!E9/HistoricalFS!E60,0) -> 1.1466085 | F20: =IFERROR(HistoricalFS!F9/HistoricalFS!F60,0) -> 1.1842971 | G20: =IFERROR(HistoricalFS!G9/HistoricalFS!G60,0) -> 1.1896229 | H20: =IFERROR(HistoricalFS!H9/HistoricalFS!H60,0) -> 1.0735966 | I20: =IFERROR(HistoricalFS!I9/HistoricalFS!I60,0) -> 1.238507 | J20: =IFERROR(HistoricalFS!J9/HistoricalFS!J60,0) -> 1.3316087 | ... L20: =IFERROR(HistoricalFS!L9/HistoricalFS!L60,0) -> 1.3501711 | N20: =IFERROR(AVERAGE(C20:L20),0) -> 1.276552 | O20: =IFERROR(MEDIAN(C20:L20),0) -> 1.2850578
B21: AR Turnover Ratio | C21: =IFERROR(HistoricalFS!C9/HistoricalFS!C66,0) -> 10.28257 | D21: =IFERROR(HistoricalFS!D9/HistoricalFS!D66,0) -> 7.534709 | E21: =IFERROR(HistoricalFS!E9/HistoricalFS!E66,0) -> 9.0089916 | F21: =IFERROR(HistoricalFS!F9/HistoricalFS!F66,0) -> 7.9064071 | G21: =IFERROR(HistoricalFS!G9/HistoricalFS!G66,0) -> 7.9776781 | H21: =IFERROR(HistoricalFS!H9/HistoricalFS!H66,0) -> 8.5640959 | I21: =IFERROR(HistoricalFS!I9/HistoricalFS!I66,0) -> 10.979214 | J21: =IFERROR(HistoricalFS!J9/HistoricalFS!J66,0) -> 10.997295 | ... L21: =IFERROR(HistoricalFS!L9/HistoricalFS!L66,0) -> 9.1809206 | N21: =IFERROR(AVERAGE(C21:L21),0) -> 9.3125034 | O21: =IFERROR(MEDIAN(C21:L21),0) -> 9.0949561
B23: Profitability Ratio
B24: Gross Profit Margin | C24: =IFERROR(HistoricalFS!C16,0) -> 0.40139367 | D24: =IFERROR(HistoricalFS!D16,0) -> 0.38774175 | E24: =IFERROR(HistoricalFS!E16,0) -> 0.40516794 | F24: =IFERROR(HistoricalFS!F16,0) -> 0.41592578 | G24: =IFERROR(HistoricalFS!G16,0) -> 0.41132152 | H24: =IFERROR(HistoricalFS!H16,0) -> 0.4170521 | I24: =IFERROR(HistoricalFS!I16,0) -> 0.4055249 | J24: =IFERROR(HistoricalFS!J16,0) -> 0.36928115 | ... L24: =IFERROR(HistoricalFS!L16,0) -> 0.42247045 | N24: =IFERROR(AVERAGE(C24:L24),0) -> 0.40044713 | O24: =IFERROR(MEDIAN(C24:L24),0) -> 0.40534642
B25: Net Profit Margin | C25: =IFERROR(HistoricalFS!C40,0) -> 0.10919904 | D25: =IFERROR(HistoricalFS!D40,0) -> 0.12970982 | E25: =IFERROR(HistoricalFS!E40,0) -> 0.13290915 | F25: =IFERROR(HistoricalFS!F40,0) -> 0.137183 | G25: =IFERROR(HistoricalFS!G40,0) -> 0.19192503 | H25: =IFERROR(HistoricalFS!H40,0) -> 0.14777011 | I25: =IFERROR(HistoricalFS!I40,0) -> 0.153983 | J25: =IFERROR(HistoricalFS!J40,0) -> 0.13889301 | ... L25: =IFERROR(HistoricalFS!L40,0) -> 0.1169124 | N25: =IFERROR(AVERAGE(C25:L25),0) -> 0.13777519 | O25: =IFERROR(MEDIAN(C25:L25),0) -> 0.13504607
B26: ROIC | C26: =ROIC!F42 -> 0.21885321 | D26: =ROIC!G42 -> 0.25190129 | E26: =ROIC!H42 -> 0.23989399 | F26: =ROIC!I42 -> 0.24967249 | G26: =ROIC!J42 -> 0.21351801 | H26: =ROIC!K42 -> 0.19617668 | I26: =ROIC!L42 -> 0.22189307 | J26: =ROIC!M42 -> 0.19955086 | ... L26: =ROIC!O42 -> 0.232386 | N26: =IFERROR(AVERAGE(C26:L26),0) -> 0.22164543 | O26: =IFERROR(MEDIAN(C26:L26),0) -> 0.22037314
B27: EBITDA Margin | C27: =IFERROR(HistoricalFS!C22,0) -> 0.16667775 | D27: =IFERROR(HistoricalFS!D22,0) -> 0.19674782 | E27: =IFERROR(HistoricalFS!E22,0) -> 0.20573247 | F27: =IFERROR(HistoricalFS!F22,0) -> 0.21166944 | G27: =IFERROR(HistoricalFS!G22,0) -> 0.20666082 | H27: =IFERROR(HistoricalFS!H22,0) -> 0.21731344 | I27: =IFERROR(HistoricalFS!I22,0) -> 0.21754852 | J27: =IFERROR(HistoricalFS!J22,0) -> 0.19624323 | ... L27: =IFERROR(HistoricalFS!L22,0) -> 0.20979689 | N27: =IFERROR(AVERAGE(C27:L27),0) -> 0.20118693 | O27: =IFERROR(MEDIAN(C27:L27),0) -> 0.20619665
B28: EBIT Margin | C28: =IFERROR((HistoricalFS!C21-HistoricalFS!C24)/HistoricalFS!C9,0) -> 0.1557049 | D28: =IFERROR((HistoricalFS!D21-HistoricalFS!D24)/HistoricalFS!D9,0) -> 0.18480202 | E28: =IFERROR((HistoricalFS!E21-HistoricalFS!E24)/HistoricalFS!E9,0) -> 0.19045718 | F28: =IFERROR((HistoricalFS!F21-HistoricalFS!F24)/HistoricalFS!F9,0) -> 0.19586024 | G28: =IFERROR((HistoricalFS!G21-HistoricalFS!G24)/HistoricalFS!G9,0) -> 0.19018086 | H28: =IFERROR((HistoricalFS!H21-HistoricalFS!H24)/HistoricalFS!H9,0) -> 0.19740788 | I28: =IFERROR((HistoricalFS!I21-HistoricalFS!I24)/HistoricalFS!I9,0) -> 0.1990648 | J28: =IFERROR((HistoricalFS!J21-HistoricalFS!J24)/HistoricalFS!J9,0) -> 0.17914308 | ... L28: =IFERROR((HistoricalFS!L21-HistoricalFS!L24)/HistoricalFS!L9,0) -> 0.19270281 | N28: =IFERROR(AVERAGE(C28:L28),0) -> 0.18510578 | O28: =IFERROR(MEDIAN(C28:L28),0) -> 0.19031902
B29: EBT Margin | C29: =IFERROR(HistoricalFS!C34,0) -> 0.14211153 | D29: =IFERROR(HistoricalFS!D34,0) -> 0.16960237 | E29: =IFERROR(HistoricalFS!E34,0) -> 0.1738202 | F29: =IFERROR(HistoricalFS!F34,0) -> 0.17828002 | G29: =IFERROR(HistoricalFS!G34,0) -> 0.16708582 | H29: =IFERROR(HistoricalFS!H34,0) -> 0.17438955 | I29: =IFERROR(HistoricalFS!I34,0) -> 0.18658363 | J29: =IFERROR(HistoricalFS!J34,0) -> 0.16918421 | ... L29: =IFERROR(HistoricalFS!L34,0) -> 0.17074143 | N29: =IFERROR(AVERAGE(C29:L29),0) -> 0.16833784 | O29: =IFERROR(MEDIAN(C29:L29),0) -> 0.1701719
B31: Growth Ratio
B32: SalesGrowth | C32: - | D32: =IFERROR(HistoricalFS!D10,0) -> 0.018219179 | E32: =IFERROR(HistoricalFS!E10,0) -> 0.10019492 | F32: =IFERROR(HistoricalFS!F10,0) -> 0.06252974 | G32: =IFERROR(HistoricalFS!G10,0) -> 0.047414402 | H32: =IFERROR(HistoricalFS!H10,0) -> -0.039124171 | I32: =IFERROR(HistoricalFS!I10,0) -> 0.11278807 | J32: =IFERROR(HistoricalFS!J10,0) -> 0.11314924 | K32: =IFERROR(HistoricalFS!K10,0) -> 0.084671527 | L32: =IFERROR(HistoricalFS!L10,0) -> 0.058586795 | N32: =IFERROR(AVERAGE(D32:L32),0) -> 0.062047745 | O32: =IFERROR(MEDIAN(C32:L32),0) -> 0.06252974
B33: EBITDA Growth | C33: - | D33: =IFERROR(HistoricalFS!D21/HistoricalFS!C21-1,0) -> 0.2019145 | E33: =IFERROR(HistoricalFS!E21/HistoricalFS!D21-1,0) -> 0.15043623 | F33: =IFERROR(HistoricalFS!F21/HistoricalFS!E21-1,0) -> 0.093191938 | G33: =IFERROR(HistoricalFS!G21/HistoricalFS!F21-1,0) -> 0.022630013 | H33: =IFERROR(HistoricalFS!H21/HistoricalFS!G21-1,0) -> 0.010405476 | I33: =IFERROR(HistoricalFS!I21/HistoricalFS!H21-1,0) -> 0.11399187 | J33: =IFERROR(HistoricalFS!J21/HistoricalFS!I21-1,0) -> 0.0041346082 | K33: =IFERROR(HistoricalFS!K21/HistoricalFS!J21-1,0) -> 0.014120987 | L33: =IFERROR(HistoricalFS!L21/HistoricalFS!K21-1,0) -> 0.21042895 | N33: =IFERROR(AVERAGE(D33:L33),0) -> 0.091250508 | O33: =IFERROR(MEDIAN(C33:L33),0) -> 0.093191938
B34: EBIT Growth | C34: - | D34: =IFERROR(HistoricalFS!D33/HistoricalFS!C33-1,0) -> 0.21518912 | E34: =IFERROR(HistoricalFS!E33/HistoricalFS!D33-1,0) -> 0.12755563 | F34: =IFERROR(HistoricalFS!F33/HistoricalFS!E33-1,0) -> 0.089791738 | G34: =IFERROR(HistoricalFS!G33/HistoricalFS!F33-1,0) -> -0.0183527 | H34: =IFERROR(HistoricalFS!H33/HistoricalFS!G33-1,0) -> 0.0028780652 | I34: =IFERROR(HistoricalFS!I33/HistoricalFS!H33-1,0) -> 0.19059907 | J34: =IFERROR(HistoricalFS!J33/HistoricalFS!I33-1,0) -> 0.0093451131 | K34: =IFERROR(HistoricalFS!K33/HistoricalFS!J33-1,0) -> -0.028194647 | L34: =IFERROR(HistoricalFS!L33/HistoricalFS!K33-1,0) -> 0.19240697 | N34: =IFERROR(AVERAGE(D34:L34),0) -> 0.08680204 | O34: =IFERROR(MEDIAN(C34:L34),0) -> 0.089791738
B35: Net Profit Growth | C35: - | D35: =IFERROR(HistoricalFS!D39/HistoricalFS!C39-1,0) -> 0.20947068 | E35: =IFERROR(HistoricalFS!E39/HistoricalFS!D39-1,0) -> 0.12733147 | F35: =IFERROR(HistoricalFS!F39/HistoricalFS!E39-1,0) -> 0.096696677 | G35: =IFERROR(HistoricalFS!G39/HistoricalFS!F39-1,0) -> 0.46537864 | H35: =IFERROR(HistoricalFS!H39/HistoricalFS!G39-1,0) -> -0.2601865 | I35: =IFERROR(HistoricalFS!I39/HistoricalFS!H39-1,0) -> 0.15957447 | J35: =IFERROR(HistoricalFS!J39/HistoricalFS!I39-1,0) -> 0.0040630778 | K35: =IFERROR(HistoricalFS!K39/HistoricalFS!J39-1,0) -> -0.068593413 | L35: =IFERROR(HistoricalFS!L39/HistoricalFS!K39-1,0) -> 0.03768512 | N35: =IFERROR(AVERAGE(D35:L35),0) -> 0.085713356 | O35: =IFERROR(MEDIAN(C35:L35),0) -> 0.096696677
B36: Dividend Growth | C36: - | D36: =IFERROR(HistoricalFS!D47/HistoricalFS!C47-1,0) -> 0.045570291 | E36: =IFERROR(HistoricalFS!E47/HistoricalFS!D47-1,0) -> 1.6089177 | F36: =IFERROR(HistoricalFS!F47/HistoricalFS!E47-1,0) -> 0.3332681 | G36: =IFERROR(HistoricalFS!G47/HistoricalFS!F47-1,0) -> 0.50007339 | H36: =IFERROR(HistoricalFS!H47/HistoricalFS!G47-1,0) -> -0.2 | I36: =IFERROR(HistoricalFS!I47/HistoricalFS!H47-1,0) -> -1 | J36: =IFERROR(HistoricalFS!J47/HistoricalFS!I47-1,0) -> 0 | K36: =IFERROR(HistoricalFS!K47/HistoricalFS!J47-1,0) -> 0 | L36: =IFERROR(HistoricalFS!L47/HistoricalFS!K47-1,0) -> 0 | N36: =IFERROR(AVERAGE(D36:L36),0) -> 0.14309217 | O36: =IFERROR(MEDIAN(C36:L36),0) -> 0
B38: Cash Conversion Cycle
B39: Debtor Days | C39: =IFERROR(365/C21,0) -> 35.496963 | D39: =IFERROR(365/D21,0) -> 48.442481 | E39: =IFERROR(365/E21,0) -> 40.515078 | F39: =IFERROR(365/F21,0) -> 46.165091 | G39: =IFERROR(365/G21,0) -> 45.752661 | H39: =IFERROR(365/H21,0) -> 42.619794 | I39: =IFERROR(365/I21,0) -> 33.24464 | J39: =IFERROR(365/J21,0) -> 33.189981 | ... L39: =IFERROR(365/L21,0) -> 39.756362 | N39: =IFERROR(AVERAGE(C39:L39),0) -> 39.931704 | O39: =IFERROR(MEDIAN(C39:L39),0) -> 40.13572
B40: Payable Days | C40: =IFERROR(365/([5]HistoricalFS!C9/[5]HistoricalFS!C57),0) -> 92.524697 | D40: =IFERROR(365/([5]HistoricalFS!D9/[5]HistoricalFS!D57),0) -> 109.21819 | E40: =IFERROR(365/([5]HistoricalFS!E9/[5]HistoricalFS!E57),0) -> 143.25129 | F40: =IFERROR(365/([5]HistoricalFS!F9/[5]HistoricalFS!F57),0) -> 151.89038 | G40: =IFERROR(365/([5]HistoricalFS!G9/[5]HistoricalFS!G57),0) -> 121.89551 | H40: =IFERROR(365/([5]HistoricalFS!H9/[5]HistoricalFS!H57),0) -> 125.47289 | I40: =IFERROR(365/([5]HistoricalFS!I9/[5]HistoricalFS!I57),0) -> 97.331833 | J40: =IFERROR(365/([5]HistoricalFS!J9/[5]HistoricalFS!J57),0) -> 83.898118 | ... L40: =IFERROR(365/([5]HistoricalFS!L9/[5]HistoricalFS!L57),0) -> 66.580649 | N40: =IFERROR(AVERAGE(C40:L40),0) -> 106.0959 | O40: =IFERROR(MEDIAN(C40:L40),0) -> 103.27501
B41: Inventory Days | C41: =IFERROR(365/C19,0) -> 47.282371 | D41: =IFERROR(365/D19,0) -> 56.630401 | E41: =IFERROR(365/E19,0) -> 55.628777 | F41: =IFERROR(365/F19,0) -> 58.478994 | G41: =IFERROR(365/G19,0) -> 55.154799 | H41: =IFERROR(365/H19,0) -> 62.723372 | I41: =IFERROR(365/I19,0) -> 56.800511 | J41: =IFERROR(365/J19,0) -> 63.32385 | ... L41: =IFERROR(365/L19,0) -> 32.908781 | N41: =IFERROR(AVERAGE(C41:L41),0) -> 53.106621 | O41: =IFERROR(MEDIAN(C41:L41),0) -> 56.129589
B42: Cash Conversion Cycle (in days) | C42: =IFERROR(SUM(C39,C41)-C40,0) -> -9.745363 | D42: =IFERROR(SUM(D39,D41)-D40,0) -> -4.1453048 | E42: =IFERROR(SUM(E39,E41)-E40,0) -> -47.107433 | F42: =IFERROR(SUM(F39,F41)-F40,0) -> -47.246292 | G42: =IFERROR(SUM(G39,G41)-G40,0) -> -20.988047 | H42: =IFERROR(SUM(H39,H41)-H40,0) -> -20.129727 | I42: =IFERROR(SUM(I39,I41)-I40,0) -> -7.2866823 | J42: =IFERROR(SUM(J39,J41)-J40,0) -> 12.615713 | ... L42: =IFERROR(SUM(L39,L41)-L40,0) -> 6.0844942 | N42: =IFERROR(AVERAGE(C42:L42),0) -> -13.057571 | O42: =IFERROR(MEDIAN(C42:L42),0) -> -8.5160226

Sheet ROIC
B2: ='Data Sheet'!B1 -> GODREJ CONSUMER PRODUCTS LTD
B3: (GODREJCP | BSE Code: 532424)
B5: ROIC - GODREJ CONSUMER PRODUCTS LTD
B7: Calculation of ROIC | F7: ='Raw FS'!E$1 -> 42064 | G7: ='Raw FS'!F$1 -> 42430 | H7: ='Raw FS'!G$1 -> 42795 | I7: ='Raw FS'!H$1 -> 43160 | J7: ='Raw FS'!I$1 -> 43525 | K7: ='Raw FS'!J$1 -> 43891 | L7: ='Raw FS'!K$1 -> 44256 | M7: ='Raw FS'!L$1 -> 44621 | ... O7: ='Raw FS'!N$1 -> 45352
B9: Current Assets
B10: ='Raw FS'!B35 -> Inventories | F10: ='Raw FS'!E35 -> 1072 | G10: ='Raw FS'!F35 -> 1307 | H10: ='Raw FS'!G35 -> 1412 | I10: ='Raw FS'!H35 -> 1578 | J10: ='Raw FS'!I35 -> 1559 | K10: ='Raw FS'!J35 -> 1703 | L10: ='Raw FS'!K35 -> 1716 | M10: ='Raw FS'!L35 -> 2130 | ... O10: ='Raw FS'!N35 -> 1271
B11: ='Raw FS'!B36 -> Trade receivables | F11: ='Raw FS'!E36 -> 805 | G11: ='Raw FS'!F36 -> 1118 | H11: ='Raw FS'!G36 -> 1029 | I11: ='Raw FS'!H36 -> 1246 | J11: ='Raw FS'!I36 -> 1293 | K11: ='Raw FS'!J36 -> 1157 | L11: ='Raw FS'!K36 -> 1004 | M11: ='Raw FS'!L36 -> 1116 | ... O11: ='Raw FS'!N36 -> 1535
B12: ='Raw FS'!B39 -> Other asset items | F12: ='Raw FS'!E39 -> 393 | G12: ='Raw FS'!F39 -> 335 | H12: ='Raw FS'!G39 -> 472 | I12: ='Raw FS'!H39 -> 684 | J12: ='Raw FS'!I39 -> 1109 | K12: ='Raw FS'!J39 -> 1289 | L12: ='Raw FS'!K39 -> 1209 | M12: ='Raw FS'!L39 -> 1377 | ... O12: ='Raw FS'!N39 -> 1012
B13: Total Current Assets | F13: =SUM(F10:F12) -> 2270 | G13: =SUM(G10:G12) -> 2760 | H13: =SUM(H10:H12) -> 2913 | I13: =SUM(I10:I12) -> 3508 | J13: =SUM(J10:J12) -> 3961 | K13: =SUM(K10:K12) -> 4149 | L13: =SUM(L10:L12) -> 3929 | M13: =SUM(M10:M12) -> 4623 | ... O13: =SUM(O10:O12) -> 3818
B15: Current Liabilities
B16: ='Raw FS'!B11 -> Trade Payables | F16: ='Raw FS'!E11 -> 1088 | G16: ='Raw FS'!F11 -> 1485 | H16: ='Raw FS'!G11 -> 1724 | I16: ='Raw FS'!H11 -> 2353 | J16: ='Raw FS'!I11 -> 2540 | K16: ='Raw FS'!J11 -> 2480 | L16: ='Raw FS'!K11 -> 2012 | M16: ='Raw FS'!L11 -> 2163 | ... O16: ='Raw FS'!N11 -> 1675
B17: ='Raw FS'!B12 -> Advance from Customers | F17: ='Raw FS'!E12 -> 0 | G17: ='Raw FS'!F12 -> 0 | H17: ='Raw FS'!G12 -> 0 | I17: ='Raw FS'!H12 -> 0 | J17: ='Raw FS'!I12 -> 0 | K17: ='Raw FS'!J12 -> 25 | L17: ='Raw FS'!K12 -> 27 | M17: ='Raw FS'!L12 -> 30 | ... O17: ='Raw FS'!N12 -> 30
B18: ='Raw FS'!B13 -> Other liability items | F18: ='Raw FS'!E13 -> 847 | G18: ='Raw FS'!F13 -> 1026 | H18: ='Raw FS'!G13 -> 1913 | I18: ='Raw FS'!H13 -> 1745 | J18: ='Raw FS'!I13 -> 905 | K18: ='Raw FS'!J13 -> 901 | L18: ='Raw FS'!K13 -> 901 | M18: ='Raw FS'!L13 -> 629 | ... O18: ='Raw FS'!N13 -> 865
B19: Total Current Liabilities | F19: =SUM(F16:F18) -> 1935 | G19: =SUM(G16:G18) -> 2511 | H19: =SUM(H16:H18) -> 3637 | I19: =SUM(I16:I18) -> 4098 | J19: =SUM(J16:J18) -> 3445 | K19: =SUM(K16:K18) -> 3406 | L19: =SUM(L16:L18) -> 2940 | M19: =SUM(M16:M18) -> 2822 | ... O19: =SUM(O16:O18) -> 2570
B21: Net Working Capital | F21: =F13-F19 -> 335 | G21: =G13-G19 -> 249 | H21: =H13-H19 -> -724 | I21: =I13-I19 -> -590 | J21: =J13-J19 -> 516 | K21: =K13-K19 -> 743 | L21: =L13-L19 -> 989 | M21: =M13-M19 -> 1801 | ... O21: =O13-O19 -> 1248
B23: Non Current Assets
B24: ='Raw FS'!B17 -> Land | F24: ='Raw FS'!E17 -> 54 | G24: ='Raw FS'!F17 -> 86 | H24: ='Raw FS'!G17 -> 108 | I24: ='Raw FS'!H17 -> 118 | J24: ='Raw FS'!I17 -> 147 | K24: ='Raw FS'!J17 -> 146 | L24: ='Raw FS'!K17 -> 144 | M24: ='Raw FS'!L17 -> 147 | ... O24: ='Raw FS'!N17 -> 157
B25: ='Raw FS'!B18 -> Building | F25: ='Raw FS'!E18 -> 249 | G25: ='Raw FS'!F18 -> 390 | H25: ='Raw FS'!G18 -> 430 | I25: ='Raw FS'!H18 -> 537 | J25: ='Raw FS'!I18 -> 627 | K25: ='Raw FS'!J18 -> 699 | L25: ='Raw FS'!K18 -> 757 | M25: ='Raw FS'!L18 -> 812 | ... O25: ='Raw FS'!N18 -> 791
B26: ='Raw FS'!B19 -> Plant Machinery | F26: ='Raw FS'!E19 -> 547 | G26: ='Raw FS'!F19 -> 343 | H26: ='Raw FS'!G19 -> 435 | I26: ='Raw FS'!H19 -> 517 | J26: ='Raw FS'!I19 -> 634 | K26: ='Raw FS'!J19 -> 713 | L26: ='Raw FS'!K19 -> 809 | M26: ='Raw FS'!L19 -> 942 | ... O26: ='Raw FS'!N19 -> 1186
B27: ='Raw FS'!B20 -> Ships Vessels | F27: ='Raw FS'!E20 -> 0 | G27: ='Raw FS'!F20 -> 0 | H27: ='Raw FS'!G20 -> 0 | I27: ='Raw FS'!H20 -> 0 | J27: ='Raw FS'!I20 -> 0 | K27: ='Raw FS'!J20 -> 0 | L27: ='Raw FS'!K20 -> 1 | M27: ='Raw FS'!L20 -> 2 | ... O27: ='Raw FS'!N20 -> 17
B28: ='Raw FS'!B21 -> Equipments | F28: ='Raw FS'!E21 -> 19 | G28: ='Raw FS'!F21 -> 14 | H28: ='Raw FS'!G21 -> 17 | I28: ='Raw FS'!H21 -> 24 | J28: ='Raw FS'!I21 -> 30 | K28: ='Raw FS'!J21 -> 33 | L28: ='Raw FS'!K21 -> 36 | M28: ='Raw FS'!L21 -> 41 | ... O28: ='Raw FS'!N21 -> 47
B29: ='Raw FS'!B22 -> Computers | F29: ='Raw FS'!E22 -> 34 | G29: ='Raw FS'!F22 -> 24 | H29: ='Raw FS'!G22 -> 38 | I29: ='Raw FS'!H22 -> 47 | J29: ='Raw FS'!I22 -> 55 | K29: ='Raw FS'!J22 -> 59 | L29: ='Raw FS'!K22 -> 64 | M29: ='Raw FS'!L22 -> 75 | ... O29: ='Raw FS'!N22 -> 67
B30: ='Raw FS'!B23 -> Furniture n fittings | F30: ='Raw FS'!E23 -> 29 | G30: ='Raw FS'!F23 -> 21 | H30: ='Raw FS'!G23 -> 25 | I30: ='Raw FS'!H23 -> 32 | J30: ='Raw FS'!I23 -> 35 | K30: ='Raw FS'!J23 -> 35 | L30: ='Raw FS'!K23 -> 37 | M30: ='Raw FS'!L23 -> 36 | ... O30: ='Raw FS'!N23 -> 30
B31: ='Raw FS'!B24 -> Vehicles | F31: ='Raw FS'!E24 -> 49 | G31: ='Raw FS'!F24 -> 41 | H31: ='Raw FS'!G24 -> 47 | I31: ='Raw FS'!H24 -> 47 | J31: ='Raw FS'!I24 -> 48 | K31: ='Raw FS'!J24 -> 44 | L31: ='Raw FS'!K24 -> 60 | M31: ='Raw FS'!L24 -> 65 | ... O31: ='Raw FS'!N24 -> 31
B32: ='Raw FS'!B25 -> Intangible Assets | F32: ='Raw FS'!E25 -> 5285 | G32: ='Raw FS'!F25 -> 5050 | H32: ='Raw FS'!G25 -> 7123 | I32: ='Raw FS'!H25 -> 7245 | J32: ='Raw FS'!I25 -> 7433 | K32: ='Raw FS'!J25 -> 8036 | L32: ='Raw FS'!K25 -> 7753 | M32: ='Raw FS'!L25 -> 8083 | ... O32: ='Raw FS'!N25 -> 10696
B33: ='Raw FS'!B26 -> Other fixed assets | F33: ='Raw FS'!E26 -> 67 | G33: ='Raw FS'!F26 -> 55 | H33: ='Raw FS'!G26 -> 67 | I33: ='Raw FS'!H26 -> 107 | J33: ='Raw FS'!I26 -> 119 | K33: ='Raw FS'!J26 -> 126 | L33: ='Raw FS'!K26 -> 130 | M33: ='Raw FS'!L26 -> 144 | ... O33: ='Raw FS'!N26 -> 151
B35: Gross Block | F35: =SUM(F24:F34) -> 6333 | G35: =SUM(G24:G34) -> 6024 | H35: =SUM(H24:H34) -> 8290 | I35: =SUM(I24:I34) -> 8674 | J35: =SUM(J24:J34) -> 9128 | K35: =SUM(K24:K34) -> 9891 | L35: =SUM(L24:L34) -> 9791 | M35: =SUM(M24:M34) -> 10347 | ... O35: =SUM(O24:O34) -> 13173
B36: Accumulated Depreciation | F36: =-'Raw FS'!E28 -> -782 | G36: =-'Raw FS'!F28 -> -93 | H36: =-'Raw FS'!G28 -> -208 | I36: =-'Raw FS'!H28 -> -359 | J36: =-'Raw FS'!I28 -> -457 | K36: =-'Raw FS'!J28 -> -661 | L36: =-'Raw FS'!K28 -> -886 | M36: =-'Raw FS'!L28 -> -1127 | ... O36: =-'Raw FS'!N28 -> -2732
B37: Net Non Current Assets | F37: =SUM(F35:F36) -> 5551 | G37: =SUM(G35:G36) -> 5931 | H37: =SUM(H35:H36) -> 8082 | I37: =SUM(I35:I36) -> 8315 | J37: =SUM(J35:J36) -> 8671 | K37: =SUM(K35:K36) -> 9230 | L37: =SUM(L35:L36) -> 8905 | M37: =SUM(M35:M36) -> 9220 | ... O37: =SUM(O35:O36) -> 10441
B39: Invested Capital | F39: =F37+F21 -> 5886 | G39: =G37+G21 -> 6180 | H39: =H37+H21 -> 7358 | I39: =I37+I21 -> 7725 | J39: =J37+J21 -> 9187 | K39: =K37+K21 -> 9973 | L39: =L37+L21 -> 9894 | M39: =M37+M21 -> 11021 | ... O39: =O37+O21 -> 11689
B40: EBIT | F40: =HistoricalFS!C33+HistoricalFS!C30 -> 1288.17 | G40: =HistoricalFS!D33+HistoricalFS!D30 -> 1556.75 | H40: =HistoricalFS!E33+HistoricalFS!E30 -> 1765.14 | I40: =HistoricalFS!F33+HistoricalFS!F30 -> 1928.72 | J40: =HistoricalFS!G33+HistoricalFS!G30 -> 1961.59 | K40: =HistoricalFS!H33+HistoricalFS!H30 -> 1956.47 | L40: =HistoricalFS!I33+HistoricalFS!I30 -> 2195.41 | M40: =HistoricalFS!J33+HistoricalFS!J30 -> 2199.25 | ... O40: =HistoricalFS!L33+HistoricalFS!L30 -> 2716.36
B42: ROIC | F42: =F40/F39 -> 0.21885321 | G42: =G40/G39 -> 0.25190129 | H42: =H40/H39 -> 0.23989399 | I42: =I40/I39 -> 0.24967249 | J42: =J40/J39 -> 0.21351801 | K42: =K40/K39 -> 0.19617668 | L42: =L40/L39 -> 0.22189307 | M42: =M40/M39 -> 0.19955086 | ... O42: =O40/O39 -> 0.232386

Sheet Forcasting
B2: ='[2]Data Sheet'!B1 -> GODREJ CONSUMER PRODUCTS LTD
B3: (GODREJCP | BSE Code: 532424)
B5: Forecasting - GODREJ CONSUMER PRODUCTS LTD
B8: Year Weight | C8: Year | D8: Sales | E8: Sales Growth | G8: Year Weight | H8: Year | I8: EBIT | J8: EBIT Growth | L8: Year Weight | M8: Year | N8: EPS | O8: EPS Growth
B9: 1 | C9: ='[2]Data Sheet'!$B$16 -> 42094 | D9: {=TRANSPOSE('Data Sheet'!B17:K17)} -> 8273.15 | E9: - | G9: 1 | H9: ='[2]Data Sheet'!$B$16 -> 42094 | I9: {=TRANSPOSE(HistoricalFS!C27:L27)} -> 1288.17 | J9: - | L9: 1 | M9: ='[2]Data Sheet'!$B$16 -> 42094 | N9: {=TRANSPOSE(HistoricalFS!C44:L44)} -> 8.8449187
B10: =B9+1 -> 2 | C10: =C9+365 -> 42459 | D10: 8423.88 | E10: =D10/D9-1 -> 0.018219179 | G10: =G9+1 -> 2 | H10: =H9+365 -> 42459 | I10: 1556.75 | J10: =I10/I9-1 -> 0.20849733 | L10: =L9+1 -> 2 | M10: =M9+365 -> 42459 | N10: 10.695576 | O10: =N10/N9-1 -> 0.2092339
B11: =B10+1 -> 3 | C11: =C10+365 -> 42824 | D11: 9267.91 | E11: =D11/D10-1 -> 0.10019492 | G11: =G10+1 -> 3 | H11: =H10+365 -> 42824 | I11: 1765.14 | J11: =I11/I10-1 -> 0.13386221 | L11: =L10+1 -> 3 | M11: =M10+365 -> 42824 | N11: 12.055099 | O11: =N11/N10-1 -> 0.12711081
B12: =B11+1 -> 4 | C12: =C11+365 -> 43189 | D12: 9847.43 | E12: =D12/D11-1 -> 0.06252974 | G12: =G11+1 -> 4 | H12: =H11+365 -> 43189 | I12: 1928.72 | J12: =I12/I11-1 -> 0.092672536 | L12: =L11+1 -> 4 | M12: =M11+365 -> 43189 | N12: 13.2182 | O12: =N12/N11-1 -> 0.096482059
B13: =B12+1 -> 5 | C13: =C12+365 -> 43554 | D13: 10314.34 | E13: =D13/D12-1 -> 0.047414402 | G13: =G12+1 -> 5 | H13: =H12+365 -> 43554 | I13: 1961.59 | J13: =I13/I12-1 -> 0.017042391 | L13: =L12+1 -> 5 | M13: =M12+365 -> 43554 | N13: 19.365878 | O13: =N13/N12-1 -> 0.46509193
B14: =B13+1 -> 6 | C14: =C13+365 -> 43919 | D14: 9910.8 | E14: =D14/D13-1 -> -0.039124171 | G14: =G13+1 -> 6 | H14: =H13+365 -> 43919 | I14: 1956.47 | J14: =I14/I13-1 -> -0.0026101275 | L14: =L13+1 -> 6 | M14: =M13+365 -> 43919 | N14: 14.325736 | O14: =N14/N13-1 -> -0.26025887
B15: =B14+1 -> 7 | C15: =C14+365 -> 44284 | D15: 11028.62 | E15: =D15/D14-1 -> 0.11278807 | G15: =G14+1 -> 7 | H15: =H14+365 -> 44284 | I15: 2195.41 | J15: =I15/I14-1 -> 0.12212812 | L15: =L14+1 -> 7 | M15: =M14+365 -> 44284 | N15: 16.608509 | O15: =N15/N14-1 -> 0.15934766
B16: =B15+1 -> 8 | C16: =C15+365 -> 44649 | D16: 12276.5 | E16: =D16/D15-1 -> 0.11314924 | G16: =G15+1 -> 8 | H16: =H15+365 -> 44649 | I16: 2199.25 | J16: =I16/I15-1 -> 0.0017491038 | L16: =L15+1 -> 8 | M16: =M15+365 -> 44649 | N16: 16.674359 | O16: =N16/N15-1 -> 0.0039648905
B17: =B16+1 -> 9 | C17: =C16+365 -> 45014 | D17: 13315.97 | E17: =D17/D16-1 -> 0.084671527 | G17: =G16+1 -> 9 | H17: =H16+365 -> 45014 | I17: 2206.91 | J17: =I17/I16-1 -> 0.0034830056 | L17: =L16+1 -> 9 | M17: =M16+365 -> 45014 | N17: 15.52909 | O17: =N17/N16-1 -> -0.068684486
B18: =B17+1 -> 10 | C18: =C17+365 -> 45379 | D18: 14096.11 | E18: =D18/D17-1 -> 0.058586795 | G18: =G17+1 -> 10 | H18: =H17+365 -> 45379 | I18: 2716.36 | J18: =I18/I17-1 -> 0.23084312 | L18: =L17+1 -> 10 | M18: =M17+365 -> 45379 | N18: 16.11273 | O18: =N18/N17-1 -> 0.037583665
B19: =B18+1 -> 11 | C19: =C18+365 -> 45744 | D19: =FORECAST(B19,$D$9:$D$18,$B$9:$B$18) -> 14169.946 | E19: =D19/D18-1 -> 0.0052380408 | G19: =G18+1 -> 11 | H19: =H18+365 -> 45744 | I19: =FORECAST(G19,$I$9:$I$18,$G$9:$G$18) -> 2656.488 | J19: =I19/I18-1 -> -0.022041261 | L19: =L18+1 -> 11 | M19: =M18+365 -> 45744 | N19: =FORECAST(L19,N9:N18,L9:L18) -> 18.592076 | O19: =N19/N18-1 -> 0.15387497
B20: =B19+1 -> 12 | C20: =C19+365 -> 46109 | D20: =FORECAST(B20,$D$9:$D$18,$B$9:$B$18) -> 14805.305 | E20: =D20/D19-1 -> 0.044838498 | G20: =G19+1 -> 12 | H20: =H19+365 -> 46109 | I20: =FORECAST(G20,$I$9:$I$18,$G$9:$G$18) -> 2779.9445 | J20: =I20/I19-1 -> 0.046473594 | L20: =L19+1 -> 12 | M20: =M19+365 -> 46109 | N20: =FORECAST(L20,N10:N19,L10:L19) -> 18.825545 | O20: =N20/N19-1 -> 0.012557446
B21: =B20+1 -> 13 | C21: =C20+365 -> 46474 | D21: =FORECAST(B21,$D$9:$D$18,$B$9:$B$18) -> 15440.664 | E21: =D21/D20-1 -> 0.042914286 | G21: =G20+1 -> 13 | H21: =H20+365 -> 46474 | I21: =FORECAST(G21,$I$9:$I$18,$G$9:$G$18) -> 2903.4011 | J21: =I21/I20-1 -> 0.044409715 | L21: =L20+1 -> 13 | M21: =M20+365 -> 46474 | N21: =FORECAST(L21,N11:N20,L11:L20) -> 18.996099 | O21: =N21/N20-1 -> 0.0090597434
B22: =B21+1 -> 14 | C22: =C21+365 -> 46839 | D22: =FORECAST(B22,$D$9:$D$18,$B$9:$B$18) -> 16076.023 | E22: =D22/D21-1 -> 0.04114843 | G22: =G21+1 -> 14 | H22: =H21+365 -> 46839 | I22: =FORECAST(G22,$I$9:$I$18,$G$9:$G$18) -> 3026.8576 | J22: =I22/I21-1 -> 0.042521354 | L22: =L21+1 -> 14 | M22: =M21+365 -> 46839 | N22: =FORECAST(L22,N12:N21,L12:L21) -> 19.055417 | O22: =N22/N21-1 -> 0.0031226438
B23: =B22+1 -> 15 | C23: =C22+365 -> 47204 | D23: =FORECAST(B23,$D$9:$D$18,$B$9:$B$18) -> 16711.382 | E23: =D23/D22-1 -> 0.039522155 | G23: =G22+1 -> 15 | H23: =H22+365 -> 47204 | I23: =FORECAST(G23,$I$9:$I$18,$G$9:$G$18) -> 3150.3142 | J23: =I23/I22-1 -> 0.040787034 | L23: =L22+1 -> 15 | M23: =M22+365 -> 47204 | N23: =FORECAST(L23,N13:N22,L13:L22) -> 18.985889 | O23: =N23/N22-1 -> -0.0036487199
B24: =B23+1 -> 16 | C24: =C23+365 -> 47569 | D24: =FORECAST(B24,$D$9:$D$18,$B$9:$B$18) -> 17346.741 | E24: =D24/D23-1 -> 0.038019541 | G24: =G23+1 -> 16 | H24: =H23+365 -> 47569 | I24: =FORECAST(G24,$I$9:$I$18,$G$9:$G$18) -> 3273.7707 | J24: =I24/I23-1 -> 0.039188645 | L24: =L23+1 -> 16 | M24: =M23+365 -> 47569 | N24: =FORECAST(L24,N14:N23,L14:L23) -> 20.138783 | O24: =N24/N23-1 -> 0.060723724

Sheet Beta Regression
B2: ='[2]Data Sheet'!B1 -> GODREJ CONSUMER PRODUCTS LTD
B3: (GODREJCP | BSE Code: 532424)
B5: Beta Regression - GODREJ CONSUMER PRODUCTS LTD
B7: Regression Beta - 1 Year Weekly
B9: Godrej Consumer Products Weekly Returns | F9: NIFTY Returns | I9: Beta Drifting
B11: Date | C11: Closing Price | D11: Return | F11: Closing Price | G11: Return | I11: Levered Raw Beta | J11: =K49 -> 0.740835
B12: 45208 | C12: 967.26 | F12: 19751.05 | I12: Raw Beta Weight | J12: 0.75
B13: 45215 | C13: 972.38 | D13: =C13/C12-1 -> 0.0052933027 | F13: 19542.65 | G13: =F13/F12-1 -> -0.010551338
B14: 45222 | C14: 971.49 | D14: =C14/C13-1 -> -0.00091528003 | F14: 19047.25 | G14: =F14/F13-1 -> -0.025349684 | I14: Market Beta | J14: 1
B15: 45229 | C15: 1004.41 | D15: =C15/C14-1 -> 0.033886092 | F15: 19230.6 | G15: =F15/F14-1 -> 0.0096260615 | I15: Market Beta Weight | J15: 0.25
B16: 45236 | C16: 968.59 | D16: =C16/C15-1 -> -0.035662727 | F16: 19425.35 | G16: =F16/F15-1 -> 0.010127089
B17: 45243 | C17: 985.89 | D17: =C17/C16-1 -> 0.017861014 | F17: 19731.8 | G17: =F17/F16-1 -> 0.015775778 | I17: Adjusted Beta | J17: =(J11*J12)+(J14*J15) -> 0.80562625
B18: 45250 | C18: 998.3 | D18: =C18/C17-1 -> 0.012587611 | F18: 19794.7 | G18: =F18/F17-1 -> 0.0031877477
B19: 45257 | C19: 1014.03 | D19: =C19/C18-1 -> 0.015756787 | F19: 20267.9 | G19: =F19/F18-1 -> 0.023905389
B20: 45264 | C20: 1010.22 | D20: =C20/C19-1 -> -0.0037572853 | F20: 20969.4 | G20: =F20/F19-1 -> 0.034611381
B21: 45271 | C21: 1030.59 | D21: =C21/C20-1 -> 0.020163925 | F21: 21456.65 | G21: =F21/F20-1 -> 0.023236239
B22: 45278 | C22: 1062.33 | D22: =C22/C21-1 -> 0.030797892 | F22: 21349.4 | G22: =F22/F21-1 -> -0.0049984504
B23: 45285 | C23: 1118.65 | D23: =C23/C22-1 -> 0.053015541 | F23: 21731.4 | G23: =F23/F22-1 -> 0.017892775
B24: 45292 | C24: 1206.32 | D24: =C24/C23-1 -> 0.078371251 | F24: 21710.8 | G24: =F24/F23-1 -> -0.00094793709
B25: 45299 | C25: 1142.68 | D25: =C25/C24-1 -> -0.052755488 | F25: 21894.55 | G25: =F25/F24-1 -> 0.0084635297
B26: 45306 | C26: 1136.5 | D26: =C26/C25-1 -> -0.0054083383 | F26: 21622.4 | G26: =F26/F25-1 -> -0.012430034
B27: 45313 | C27: 1144.46 | D27: =C27/C26-1 -> 0.0070039595 | F27: 21352.6 | G27: =F27/F26-1 -> -0.012477801
B28: 45320 | C28: 1223.13 | D28: =C28/C27-1 -> 0.068739842 | F28: 21853.8 | G28: =F28/F27-1 -> 0.023472551
B29: 45327 | C29: 1205.13 | D29: =C29/C28-1 -> -0.014716342 | F29: 21782.5 | G29: =F29/F28-1 -> -0.0032625905
... B48: 45460 | C48: 1351.9 | D48: =C48/C47-1 -> -0.025917413 | F48: 23501.1 | G48: =F48/F47-1 -> 0.0015128529
B49: 45467 | C49: 1370.83 | D49: =C49/C48-1 -> 0.014002515 | F49: 24010.6 | G49: =F49/F48-1 -> 0.021679836 | J49: Beta 1 | K49: =SLOPE(D12:D65,G12:G65) -> 0.740835
B50: 45474 | C50: 1368.79 | D50: =C50/C49-1 -> -0.0014881495 | F50: 24323.85 | G50: =F50/F49-1 -> 0.013046321
B51: 45481 | C51: 1438.63 | D51: =C51/C50-1 -> 0.051023166 | F51: 24502.15 | G51: =F51/F50-1 -> 0.0073302541 | J51: Beta 2 | K51: =(_xlfn.COVARIANCE.S(D12:D65,G12:G65))/_xlfn.VAR.S(G12:G65) -> 0.740835
B52: 45488 | C52: 1446.61 | D52: =C52/C51-1 -> 0.005546944 | F52: 24530.9 | G52: =F52/F51-1 -> 0.0011733664
B53: 45495 | C53: 1462.15 | D53: =C53/C52-1 -> 0.010742356 | F53: 24834.85 | G53: =F53/F52-1 -> 0.012390495 | J53: Beta 3 | K53: =K75 -> 0.740835
B54: 45502 | C54: 1453.83 | D54: =C54/C53-1 -> -0.0056902507 | F54: 24717.7 | G54: =F54/F53-1 -> -0.0047171616
B55: 45509 | C55: 1439.53 | D55: =C55/C54-1 -> -0.0098360881 | F55: 24367.5 | G55: =F55/F54-1 -> -0.014167985
B56: 45516 | C56: 1399.93 | D56: =C56/C55-1 -> -0.027508979 | F56: 24541.15 | G56: =F56/F55-1 -> 0.0071262953
B57: 45523 | C57: 1428.35 | D57: =C57/C56-1 -> 0.020301015 | F57: 24823.15 | G57: =F57/F56-1 -> 0.011490904
B58: 45530 | C58: 1481.2 | D58: =C58/C57-1 -> 0.037000735 | F58: 25235.9 | G58: =F58/F57-1 -> 0.016627624 | J58: SUMMARY OUTPUT
B59: 45537 | C59: 1443.45 | D59: =C59/C58-1 -> -0.025486092 | F59: 24852.15 | G59: =F59/F58-1 -> -0.015206511
B60: 45544 | C60: 1491.3 | D60: =C60/C59-1 -> 0.033149745 | F60: 25356.5 | G60: =F60/F59-1 -> 0.020294019 | J60: Regression Statistics
B61: 45551 | C61: 1456.6 | D61: =C61/C60-1 -> -0.023268289 | F61: 25790.95 | G61: =F61/F60-1 -> 0.017133674 | J61: Multiple R | K61: 0.34239135
B62: 45558 | C62: 1388.65 | D62: =C62/C61-1 -> -0.046649732 | F62: 26178.95 | G62: =F62/F61-1 -> 0.015044037 | J62: R Square | K62: 0.11723184
B63: 45565 | C63: 1343.25 | D63: =C63/C62-1 -> -0.032693623 | F63: 25014.6 | G63: =F63/F62-1 -> -0.044476574 | J63: Adjusted R Square | K63: 0.099922657
...

Sheet WACC
B2: ='[2]Data Sheet'!B1 -> GODREJ CONSUMER PRODUCTS LTD
B3: (GODREJCP | BSE Code: 532424)
B5: Weighted Average Cost of Capital- GODREJ CONSUMER PRODUCTS LTD
B7: All figures are in INR unless stated otherwise.
B9: Peer Comps
G10: Debt/ | H10: Debt/ | I10: Levered | J10: Unlevered
B11: Name | C11: Country | D11: Total Debt | E11: Total Equity | F11: Tax Rate 1 | G11: Equity | H11: Capital | I11: Beta 2 | J11: Beta 3
B13: Godrej Consumer | C13: India | D13: 3222.2 | E13: 136678 | F13: 0.25 | G13: =D13/E13 -> 0.023575118 | H13: =D13/(D13+E13) -> 0.023032133 | I13: 0.74 | J13: =I13/(1+(1-F13)*G13) -> 0.72714314
B14: Dabur India | C14: India | D14: 1365.09 | E14: 101269.87 | F14: 0.25 | G14: =D14/E14 -> 0.013479725 | H14: =D14/(D14+E14) -> 0.013300439 | I14: 0.69029221 | J14: =I14/(1+(1-F14)*G14) -> 0.68338335
B15: Emami | C15: India | D15: 93.95 | E15: 30592.1 | F15: 0.25 | G15: =D15/E15 -> 0.0030710543 | H15: =D15/(D15+E15) -> 0.0030616518 | I15: 0.41363446 | J15: =I15/(1+(1-F15)*G15) -> 0.41268393
B16: Jyothy Labs | C16: India | D16: 50.56 | E16: 18804.75 | F16: 0.25 | G16: =D16/E16 -> 0.0026886824 | H16: =D16/(D16+E16) -> 0.0026814728 | I16: 0.58255317 | J16: =I16/(1+(1-F16)*G16) -> 0.5813808
B17: Bajaj Consumer | C17: India | D17: 8.75 | E17: 3269.69 | F17: 0.25 | G17: =D17/E17 -> 0.0026760947 | H17: =D17/(D17+E17) -> 0.0026689523 | I17: 0.47654062 | J17: =I17/(1+(1-F17)*G17) -> 0.47558608
E19: Average | F19: =AVERAGE(F14:F17) -> 0.25 | G19: =AVERAGE(G14:G17) -> 0.0054788891 | H19: =AVERAGE(H14:H17) -> 0.0054281289 | I19: =AVERAGE(I14:I17) -> 0.54075511 | J19: =AVERAGE(J14:J17) -> 0.53825854
E20: Median | F20: =MEDIAN(F14:F17) -> 0.25 | G20: =MEDIAN(G14:G17) -> 0.0028798683 | H20: =MEDIAN(H14:H17) -> 0.0028715623 | I20: =MEDIAN(I14:I17) -> 0.52954689 | J20: =MEDIAN(J14:J17) -> 0.52848344
B23: Cost of Debt | G23: Cost of Equity
B25: Pre-tax Cost of Debt | E25: =310/3222.2 -> 0.09620756 | G25: Risk Free Rate | J25: 0.06946
B26: Tax Rate | E26: =F20 -> 0.25 | G26: Equity Risk Premium | J26: =(0.1677-J25) -> 0.09824
B27: After Tax Cost of Debt | E27: =E25*(1-E26) -> 0.07215567 | G27: Levered Beta 4 | J27: =J36 -> 0.65988322
G28: Cost of Equity | J28: =J25+(J26*J27) -> 0.13428693
B31: Capital Structure | G31: Levered Beta
D33: Current | E33: Target | G33: Comps Median Unlevered Beta | J33: =J20 -> 0.52848344
B34: Total Debt | C34: =D13 -> 3222.2 | D34: =C34/$C$36 -> 0.023032133 | E34: =H19 -> 0.0054281289 | G34: Target Debt/ Equity | J34: =E38 -> 0.0054577543
B35: Market Capitalization | C35: =E13 -> 136678 | D35: =C35/$C$36 -> 0.97696787 | E35: =E36-E34 -> 0.99457187 | G35: Tax Rate | J35: =E26 -> 0.25
B36: Total Capitalization | C36: =SUM(C34:C35) -> 139900.2 | D36: 1 | E36: 1 | G36: Levered Beta | J36: =J33*(1+(1-J34)*J35) -> 0.65988322
B38: Debt / Equity | D38: =D34/D35 -> 0.023575118 | E38: =E34/E35 -> 0.0054577543 | G38: Weighted Average Cost of Capital
B40: 1. Unlevered Beta = Levered Beta/(1+(1-Tax Rate) x Debt/Equity) | G40: Cost of Equity | J40: =J28 -> 0.13428693
B41: 2. Levered Beta = Unlevered Beta*(1+(1-Tax Rate) x Debt/Equity) | G41: Equity Weight | J41: =E35 -> 0.99457187
G43: Cost of Debt | J43: =E27 -> 0.07215567
G44: Debt Weight | J44: =E34 -> 0.0054281289
G46: WACC | J46: =(J40*J41)+(J43*J44) -> 0.13394967

Sheet DCF
B2: ='[2]Data Sheet'!B1 -> GODREJ CONSUMER PRODUCTS LTD
B3: (GODREJCP | BSE Code: 532424)
G4: 11 | H4: 12 | I4: 13 | J4: 14 | K4: 15
B5: Discounted Cash Flow - GODREJ CONSUMER PRODUCTS LTD
F6: 0 | G6: 0.5 | H6: 1.5 | I6: 2.5 | J6: 3.5 | K6: 4.5
B7: Calculation of PV of FCFF | F7: ='[2]Data Sheet'!K16 -> 45382 | G7: =F7+365 -> 45747 | H7: =G7+365 -> 46112 | I7: =H7+365 -> 46477 | J7: =I7+365 -> 46842 | K7: =J7+365 -> 47207
B9: EBIT | F9: =HistoricalFS!L21-HistoricalFS!L24 -> 2716.36 | G9: =FORECAST(G4,HistoricalFS!$C$27:$L$27,HistoricalFS!$C$7:$L$7) -> 2656.488 | H9: =FORECAST(H4,HistoricalFS!$C$27:$L$27,HistoricalFS!$C$7:$L$7) -> 2779.9445 | I9: =FORECAST(I4,HistoricalFS!$C$27:$L$27,HistoricalFS!$C$7:$L$7) -> 2903.4011 | J9: =FORECAST(J4,HistoricalFS!$C$27:$L$27,HistoricalFS!$C$7:$L$7) -> 3026.8576 | K9: =FORECAST(K4,HistoricalFS!$C$27:$L$27,HistoricalFS!$C$7:$L$7) -> 3150.3142
B11: Tax Rate | F11: 0.25 | G11: =F11 -> 0.25 | H11: =G11 -> 0.25 | I11: =H11 -> 0.25 | J11: =I11 -> 0.25 | K11: =J11 -> 0.25
B13: NOPAT | F13: =F9*(1-F11) -> 2037.27 | G13: =G9*(1-G11) -> 1992.366 | H13: =H9*(1-H11) -> 2084.9584 | I13: =I9*(1-I11) -> 2177.5508 | J13: =J9*(1-J11) -> 2270.1432 | K13: =K9*(1-K11) -> 2362.7356
B15: Add: Depreciation | F15: =HistoricalFS!L24 -> 240.96 | G15: {=TRANSPOSE(Forcasting!D19:D23)*$J$29} -> 227.86899 | H15: 238.0863 | I15: 248.3036 | J15: 258.5209 | K15: 268.73821
B17: Less: Addition in WC | F17: =E30*(HistoricalFS!L9-HistoricalFS!K9) -> 187.2336 | G17: =E30*(Forcasting!D19-Forcasting!D18) -> 17.72064 | H17: =E30*(Forcasting!D20-Forcasting!D19) -> 152.48618 | I17: =E30*(Forcasting!D21-Forcasting!D20) -> 152.48618 | J17: =E30*(Forcasting!D22-Forcasting!D21) -> 152.48618 | K17: =E30*(Forcasting!D23-Forcasting!D22) -> 152.48618
B19: Less: Capital Expenditure | F19: =J30*HistoricalFS!L9 -> 211.44165 | G19: =J30*Forcasting!D19 -> 212.54919 | H19: =J30*Forcasting!D20 -> 222.07958 | I19: =J30*Forcasting!D21 -> 231.60996 | J19: =J30*Forcasting!D22 -> 241.14035 | K19: =J30*Forcasting!D23 -> 250.67074
B21: Free Cash Flow to Firm | F21: =F13+F15-F17-F19 -> 1879.5547 | G21: =G13+G15-G17-G19 -> 1989.9652 | H21: =H13+H15-H17-H19 -> 1948.4789 | I21: =I13+I15-I17-I19 -> 2041.7583 | J21: =J13+J15-J17-J19 -> 2135.0376 | K21: =K13+K15-K17-K19 -> 2228.3169
B23: Discounting Factor | F23: =1/(1+$E$35)^F6 -> 1 | G23: =1/(1+$E$35)^G6 -> 0.93908112 | H23: =1/(1+$E$35)^H6 -> 0.82815062 | I23: =1/(1+$E$35)^I6 -> 0.73032396 | J23: =1/(1+$E$35)^J6 -> 0.64405324 | K23: =1/(1+$E$35)^K6 -> 0.56797339
B25: PV of FCFF | F25: =F23*F21 -> 1879.5547 | G25: =G23*G21 -> 1868.7387 | H25: =H23*H21 -> 1613.634 | I25: =I23*I21 -> 1491.145 | J25: =J23*J21 -> 1375.0779 | K25: =K23*K21 -> 1265.6247
B27: Assumptions
B29: Terminal Growth | E29: 0.055 | G29: Average Depreciation % Sales | J29: =AVERAGE(HistoricalFS!C25:L25) -> 0.016081148
B30: Working Capital % Sales Ratio | E30: =24% -> 0.24 | G30: CapEx % Sales Ratio | J30: 0.015
B32: Calculation of Terminal Value | G32: Sensitivity Analysis
B34: FCFF (n+1) | E34: =K21*(1+E29) -> 2350.8744 | G34: =E45 -> 24526.692 | H34: 0.12 | I34: 0.13394967 | J34: 0.15 | K34: 0.18
B35: WACC | E35: =WACC!J46 -> 0.13394967 | G35: 0.02 | H35: 21953.5 | I35: 19331.973 | J35: 17013.934 | K35: 13932.746
B36: Terminal Growth Rate | E36: =E29 -> 0.055 | G36: =G35+0.5% -> 0.025 | H36: 22696.51 | I36: 19869.733 | J36: 17399.595 | K36: 14157.796
G37: =G36+0.5% -> 0.03 | H37: 23522.077 | I37: 20459.226 | J37: 17817.395 | K37: 14397.849
B38: Terminal Value | E38: =E34/(E35-E36) -> 29776.873 | G38: =G37+0.5% -> 0.035 | H38: 24444.769 | I38: 21108.293 | J38: 18271.524 | K38: 14654.458
G39: =G38+0.5% -> 0.04 | H39: 25482.798 | I39: 21826.448 | J39: 18766.939 | K39: 14929.395
G40: =G39+0.5% -> 0.045 | H40: 26659.231 | I40: 22625.339 | J40: 19309.535 | K40: 15224.699
B41: Calculation of Enterprise Value | G41: =G40+0.5% -> 0.05 | H41: 28003.725 | I41: 23519.394 | J41: 19906.392 | K41: 15542.718
G42: =G41+0.5% -> 0.055 | H42: 29555.065 | I42: 24526.692 | J42: 20566.075 | K42: 15886.179
B43: PV of FCFF | E43: =SUM(G25:K25) -> 7614.2204 | G43: =G42+0.5% -> 0.06 | H43: 31364.961 | I43: 25670.205 | J43: 21299.057 | K43: 16258.261
B44: PV of Terminal Value | E44: =E38*K23 -> 16912.472 | G44: =G43+0.5% -> 0.065 | H44: 33503.93 | I44: 26979.564 | J44: 22118.271 | K44: 16662.698
B45: Value of Operating Asset | E45: =SUM(E43:E44) -> 24526.692 | G45: =G44+0.5% -> 0.07 | H45: 36070.692 | I45: 28493.672 | J45: 23039.888 | K45: 17103.903
G46: =G45+0.5% -> 0.075 | H46: 39207.846 | I46: 30264.628 | J46: 24084.387 | K46: 17587.127
B47: Add: Cash | E47: ='Data Sheet'!K69 -> 546.94 | G47: =G46+0.5% -> 0.08 | H47: 43129.288 | I47: 32363.845 | J47: 25278.099 | K47: 18118.673
B48: Less: Debt | E48: =SUM('Raw FS'!N5:N6) -> 3155 | G48: =G47+0.5% -> 0.085 | H48: 48171.142 | I48: 34891.913 | J48: 26655.46 | K48: 18706.172
B49: Value of Equity | E49: =E45+E47-E48 -> 21918.632 | G49: =G48+0.5% -> 0.09 | H49: 54893.614 | I49: 37995.201 | J49: 28262.381 | K49: 19358.948
B50: No. of Shares | E50: ='Data Sheet'!B6 -> 102.29245 | G50: =G49+0.5% -> 0.095 | H50: 64305.076 | I50: 41895.231 | J50: 30161.47 | K50: 20088.521
B51: Value per Share | E51: =E49/E50 -> 214.27419 | G51: =G50+0.5% -> 0.1 | H51: 78422.267 | I51: 46944.03 | J51: 32440.376 | K51: 20909.291

Sheet CCF
B2: ='[2]Data Sheet'!B1 -> GODREJ CONSUMER PRODUCTS LTD
B3: (GODREJCP | BSE Code: 532424)
G4: 11 | H4: 12 | I4: 13 | J4: 14 | K4: 15
B5: Capital Cash Flow - GODREJ CONSUMER PRODUCTS LTD
F6: 0 | G6: 0.5 | H6: 1.5 | I6: 2.5 | J6: 3.5 | K6: 4.5
B7: Calculation of PV of CCF | F7: ='[2]Data Sheet'!K16 -> 45382 | G7: =F7+365 -> 45747 | H7: =G7+365 -> 46112 | I7: =H7+365 -> 46477 | J7: =I7+365 -> 46842 | K7: =J7+365 -> 47207
B9: EBIT | F9: =HistoricalFS!L21-HistoricalFS!L24 -> 2716.36 | G9: =FORECAST(G4,HistoricalFS!$C$27:$L$27,HistoricalFS!$C$7:$L$7) -> 2656.488 | H9: =FORECAST(H4,HistoricalFS!$C$27:$L$27,HistoricalFS!$C$7:$L$7) -> 2779.9445 | I9: =FORECAST(I4,HistoricalFS!$C$27:$L$27,HistoricalFS!$C$7:$L$7) -> 2903.4011 | J9: =FORECAST(J4,HistoricalFS!$C$27:$L$27,HistoricalFS!$C$7:$L$7) -> 3026.8576 | K9: =FORECAST(K4,HistoricalFS!$C$27:$L$27,HistoricalFS!$C$7:$L$7) -> 3150.3142
B11: Tax Rate | F11: 0.25 | G11: =F11 -> 0.25 | H11: =G11 -> 0.25 | I11: =H11 -> 0.25 | J11: =I11 -> 0.25 | K11: =J11 -> 0.25
B13: NOPAT | F13: =F9*(1-F11) -> 2037.27 | G13: =G9*(1-G11) -> 1992.366 | H13: =H9*(1-H11) -> 2084.9584 | I13: =I9*(1-I11) -> 2177.5508 | J13: =J9*(1-J11) -> 2270.1432 | K13: =K9*(1-K11) -> 2362.7356
B15: Add: Depreciation | F15: =HistoricalFS!L24 -> 240.96 | G15: {=TRANSPOSE(Forcasting!D19:D23)*CCF!$J$36} -> 227.86899 | H15: 238.0863 | I15: 248.3036 | J15: 258.5209 | K15: 268.73821
B17: Less: Addition in WC | F17: =E36*(HistoricalFS!L9-HistoricalFS!K9) -> 187.2336 | G17: =E36*(Forcasting!D19-Forcasting!D18) -> 17.72064 | H17: =E36*(Forcasting!D20-Forcasting!D19) -> 152.48618 | I17: =E36*(Forcasting!D21-Forcasting!D20) -> 152.48618 | J17: =E36*(Forcasting!D22-Forcasting!D21) -> 152.48618 | K17: =E36*(Forcasting!D23-Forcasting!D22) -> 152.48618
B19: Less: Capital Expenditure | F19: =E37*HistoricalFS!L9 -> 211.44165 | G19: =E37*Forcasting!D19 -> 212.54919 | H19: =E37*Forcasting!D20 -> 222.07958 | I19: =E37*Forcasting!D21 -> 231.60996 | J19: =E37*Forcasting!D22 -> 241.14035 | K19: =E37*Forcasting!D23 -> 250.67074
B21: Free Cash Flow to Firm | F21: =F13+F15-F17-F19 -> 1879.5547 | G21: =G13+G15-G17-G19 -> 1989.9652 | H21: =H13+H15-H17-H19 -> 1948.4789 | I21: =I13+I15-I17-I19 -> 2041.7583 | J21: =J13+J15-J17-J19 -> 2135.0376 | K21: =K13+K15-K17-K19 -> 2228.3169
B23: Interest Expenses | F23: =HistoricalFS!L30 -> 309.57 | G23: {=TRANSPOSE(Forcasting!D19:D23)*CCF!$J$35} -> 237.60082 | H23: 248.25448 | I23: 258.90814 | J23: 269.56181 | K23: 280.21547
B25: Interest Shield | F25: =F23*F11 -> 77.3925 | G25: =G23*G11 -> 59.400204 | H25: =H23*H11 -> 62.06362 | I25: =I23*I11 -> 64.727036 | J25: =J23*J11 -> 67.390452 | K25: =K23*K11 -> 70.053867
B27: Capital Cash Flow to Firm | F27: =F21+F25 -> 1956.9472 | G27: =G21+G25 -> 2049.3654 | H27: =H21+H25 -> 2010.5426 | I27: =I21+I25 -> 2106.4853 | J27: =J21+J25 -> 2202.4281 | K27: =K21+K25 -> 2298.3708
B29: Discounting Factor | F29: =1/(1+$E$42)^F6 -> 1 | G29: =1/(1+$E$42)^G6 -> 0.93908112 | H29: =1/(1+$E$42)^H6 -> 0.82815062 | I29: =1/(1+$E$42)^I6 -> 0.73032396 | J29: =1/(1+$E$42)^J6 -> 0.64405324 | K29: =1/(1+$E$42)^K6 -> 0.56797339
